Workbook

Sheet SEP 01
D1: OPERACIONES DE TESORERÍA | BL1: LIBRE INVERSION | BO1: FIC LIFE USD | BP1: FIC VIDA PESOS | BQ1: FIC LATIN VIDA PESOS | BR1: PAGADURÍA
D2: CAPITALIZADORA | E2: SEGUROS BOLÍVAR | F2: COMERCIALES | G2: CAPITALIZADORA AHO | H2: SEGUROS BOLÍVAR AHO | I2: SEGUROS BOLÍVAR ARL | J2: COMERCIALES AHO | K2: CAPITALIZADORA | L2: SEGUROS BOLÍVAR | M2: COMERCIALES | N2: CAPITALIZADORA US$ | O2: CAPITALIZADORA PESOS | P2: SEGUROS BOLÍVAR US$ | Q2: SEGUROS BOLÍVAR PESOS | R2: COMERCIALES US$ | S2: COMERCIALES PESOS | T2: CAPITALIZADORA US$ | U2: CAPITALIZADORA PESOS | V2: SEGUROS BOLÍVAR US$ | W2: SEGUROS BOLÍVAR PESOS | X2: COMERCIALES US$ | Y2: COMERCIALES PESOS | Z2: CAPITALIZADORA US$ | AA2: CAPITALIZADORA PESOS | AB2: SEGUROS BOLÍVAR US$ | AC2: SEGUROS BOLÍVAR PESOS | AD2: COMERCIALES US$ | AE2: COMERCIALES PESOS | AF2: GRUPO BOLIVAR US$ | AG2: GRUPO BOLIVAR PESOS | AH2: SEISA US$ | AI2: SEISA PESOS | AJ2: RIBI US$ | AK2: RIBI PESOS | AL2: GRUPO BOLIVAR | AM2: INVERSORAS | AN2: SALUD EPS BOLIVAR | AO2: SALUD IPS BOLIVAR | AP2: SERVICIOS BOLIVAR | AQ2: SERVICIOS BOLIVAR | AR2: CAPITALIZADORA | AS2: SEGUROS BOLÍVAR | AT2: SEGUROS BOLÍVAR ARL | AU2: COMERCIALES | AV2: GRUPO BOLIVAR | AW2: CAPITALIZADORA | AX2: SEGUROS BOLÍVAR | AY2: COMERCIALES | AZ2: GRUPO BOLIVAR | BA2: CAPITALIZADORA | BB2: SEGUROS BOLÍVAR | BC2: SEGUROS BOLÍVAR ARL | BD2: COMERCIALES | BE2: CAPITALIZADORA | BF2: SEGUROS BOLÍVAR | BG2: COMERCIALES | BH2: CAPITALIZADORA | BI2: SEGUROS BOLÍVAR | BJ2: COMERCIALES | BK2: GRUPO BOLIVAR | BL2: CAPITALIZADORA AHO | BM2: SEGUROS BOLÍVAR AHO | BN2: COMERCIALES AHO | BO2: SEGUROS BOLÍVAR AHO | BP2: SEGUROS BOLÍVAR AHO | BQ2: SEGUROS BOLÍVAR AHO | BR2: SEGUROS BOLÍVAR USD | BS2: SEGUROS BOLÍVAR PESOS | BT2: COMERCIALES USD | BU2: COMERCIALES PESOS | BV2: CAPITALIZADORA | BW2: SEGUROS BOLÍVAR | BX2: COMERCIALES | BY2: CAPITALIZADORA | BZ2: SEGUROS BOLÍVAR | CA2: COMERCIALES | CB2: CAPITALIZADORA | CC2: SEGUROS BOLÍVAR | CD2: COMERCIALES | CE2: CAPITALIZADORA | CF2: SEGUROS BOLÍVAR | CG2: COMERCIALES | CH2: COMERCIALES | CI2: SEGUROS BOLÍVAR | CJ2: COMERCIALES | CK2: SEGUROS BOLÍVAR | CL2: SEGUROS BOLÍVAR | CM2: SEGUROS BOLÍVAR | CN2: SEGUROS BOLÍVAR | CO2: SEGUROS BOLÍVAR | CP2: SEGUROS BOLÍVAR | CQ2: SEGUROS BOLÍVAR | CR2: SEGUROS BOLÍVAR | CS2: SEGUROS BOLÍVAR USD | CT2: SEGUROS BOLÍVAR PESOS | CU2: COMERCIALES USD | CV2: COMERCIALES PESOS | CW2: TOTALES
D3: BANCO DAVIVIENDA | E3: BANCO DAVIVIENDA | F3: BANCO DAVIVIENDA | G3: BANCO DAVIVIENDA | H3: BANCO DAVIVIENDA | I3: BANCO DAVIVIENDA | J3: BANCO DAVIVIENDA | K3: BANCO REPUBLICA | L3: BANCO REPUBLICA | M3: BANCO REPUBLICA | N3: CITIBANK COMP | O3: CITIBANK COMP | P3: CITIBANK COMP | Q3: CITIBANK COMP | R3: CITIBANK COMP | S3: CITIBANK COMP | T3: JP MORGAN | U3: JP MORGAN | V3: JP MORGAN | W3: JP MORGAN | X3: JP MORGAN | Y3: JP MORGAN | Z3: DAVIVIENDA INT | AA3: DAVIVIENDA INT | AB3: DAVIVIENDA INT | AC3: DAVIVIENDA INT | AD3: DAVIVIENDA INT | AE3: DAVIVIENDA INT | AF3: DAVIVIENDA INT | AG3: DAVIVIENDA INT | AH3: DAVIVIENDA INT | AI3: DAVIVIENDA INT | AJ3: DAVIVIENDA INT | AK3: DAVIVIENDA INT | AL3: DAVIVIENDA | AM3: DAVIVIENDA | AQ3: FACILITIES | AR3: BANCO DE BOGOTA | AS3: BANCO DE BOGOTA | AT3: BANCO DE BOGOTA | AU3: BANCO DE BOGOTA | AV3: BANCO DE BOGOTA | AW3: ITAÚ | AX3: ITAÚ | AY3: ITAÚ | AZ3: ITAÚ | BA3: CORFIDIARIO | BB3: CORFIDIARIO | BC3: CORFIDIARIO | BD3: CORFIDIARIO | BE3: BANCO COLPATRIA | BF3: BANCO COLPATRIA | BG3: BANCO COLPATRIA | BH3: BANCOLOMBIA | BI3: BANCOLOMBIA | BJ3: BANCOLOMBIA | BK3: BANCOLOMBIA | BL3: BANCO DAVIVIENDA | BM3: BANCO DAVIVIENDA | BN3: BANCO DAVIVIENDA | BO3: BANCO DAVIVIENDA | BP3: BANCO DAVIVIENDA | BQ3: BANCO DAVIVIENDA | BR3: CITIBANK REASEGUROS | BS3: CITIBANK REASEGUROS | BT3: CITIBANK REASEGUROS | BU3: CITIBANK REASEGUROS | BV3: BANCO DE BOGOTA | BW3: BANCO DE BOGOTA | BX3: BANCO DE BOGOTA | BY3: BANCOLOMBIA | BZ3: BANCOLOMBIA | CA3: BANCOLOMBIA | CB3: BANCO POPULAR | CC3: BANCO POPULAR | CD3: BANCO POPULAR | CE3: BBVA | CF3: BBVA | CG3: BBVA | CH3: BANCO COLPATRIA | CI3: BANCO DE OCCIDENTE | CJ3: BANCO DE OCCIDENTE | CK3: CITIBANK | CL3: CITIBANK | CM3: BANCO DAVIVIENDA | CN3: BANCOLOMBIA | CO3: AV VILLAS - AHO | CP3: BANCO DE OCCIDENTE | CQ3: BANCO DE OCCIDENTE | CR3: BANCO PICHINCHA | CS3: DAVIVIENDA INT REASEGUROS | CT3: DAVIVIENDA INT REASEGUROS | CU3: DAVIVIENDA INT REASEGUROS | CV3: DAVIVIENDA INT REASEGUROS
A4: TIPO OP | B4: OP | C4: CONCEPTO | G4: 482800001265 | H4: 482800001273 | I4: 482800002024 | J4: 482800001257 | K4: 62250766-0 | L4: 62250774-0 | M4: 62250782-0 | N4: 36203301 | O4: 36203301 | P4: 36203328 | Q4: 36203328 | R4: 36025015 | S4: 36025015 | T4: 705329517 | U4: 705329517 | V4: 705300062 | W4: 705300062 | X4: 705300070 | Y4: 705300070 | Z4: 865784010 | AA4: 865784010 | AB4: 865804010 | AC4: 865804010 | AD4: 865794010 | AE4: 865794010 | AF4: 867614010 | AG4: 867614010 | AH4: 010002000127 | AI4: 010002000127 | AJ4: 010003000003 | AK4: 010003000003 | AR4: 000977298 | AS4: 000268649 | AT4: 000977280 | AU4: 000977272 | AV4: 000826701 | AW4: 005597176 | AX4: 005595639 | AY4: 005597183 | AZ4: 005595646 | BA4: 2113700 | BB4: 2114920 | BC4: 2113692 | BD4: 2113718 | BE4: 0172120172 | BF4: 0172120180 | BG4: 0172120199 | BH4: 17171123071 | BI4: 17171122902 | BJ4: 17171123003 | BK4: ´03199361537 | BL4: 482800007882 | BM4: 482800007908 | BN4: 482800007890 | BO4: 482800010001 | BP4: 482800010019 | BQ4: 482800010027 | BR4: 36024995 | BS4: 36024995 | BT4: 36903922 | BU4: 36903922 | BV4: 036273662 | BW4: 036297810 | BX4: 036273688 | BY4: 5300635932 | BZ4: 5300250331 | CA4: 5300218006 | CB4: 40195224 | CC4: 40298119 | CD4: 40299661 | CE4: 137017554 | CF4: 137008629 | CG4: 137017562 | CH4: 121010607 | CI4: 221816614 | CJ4: 221816598 | CK4: 60193029 | CL4: 60193401 | CM4: 1011143807 | CN4: 4801736642 | CO4: 65005340 | CP4: 288086051 | CQ4: 288049109 | CR4: 411166042 | CS4: 865804015 | CT4: 865804015 | CU4: 865794015 | CV4: 865794015
A5: PAGADURÍA | C5: SALDO INICIAL | D5: ='[1]AGO 29'!$D$55 -> 464621.62 | E5: ='[1]AGO 29'!$E$55 -> 7202665.2 | F5: ='[1]AGO 29'!$F$55 -> 14391884 | G5: ='[1]AGO 29'!$G$55 -> 0 | H5: ='[1]AGO 29'!$H$55 -> 0 | I5: ='[1]AGO 29'!$I$55 -> 74942.28 | J5: ='[1]AGO 29'!$J$55 -> 0 | K5: ='[1]AGO 29'!$K$55 -> 63079.012 | L5: ='[1]AGO 29'!$L$55 -> 226422.85 | M5: ='[1]AGO 29'!$M$55 -> 102258.18 | N5: ='[1]AGO 29'!$N$55 -> 120822.52 | O5: =(N5*4018.41)/1000 -> 485514.42 | P5: ='[1]AGO 29'!$P$55 -> 199831.79 | Q5: =(P5*4018.41)/1000 -> 803006.08 | R5: ='[1]AGO 29'!$R$55 -> 497759.29 | S5: =(R5*4018.41)/1000 -> 2000200.9 | T5: ='[1]AGO 29'!$T$55 -> 56516.94 | U5: =(T5*4018.41)/1000 -> 227108.24 | V5: ='[1]AGO 29'!$V$55 -> 38030203 | W5: =(V5*4018.41)/1000 -> 1.5282095e+08 | X5: ='[1]AGO 29'!$X$55 -> 1401713.4 | Y5: =(X5*4018.41)/1000 -> 5632659.1 | Z5: ='[1]AGO 29'!$Z$55 -> 9662.5275 | AA5: =(Z5*4018.41)/1000 -> 38827.997 | AB5: ='[1]AGO 29'!$AB$55 -> 7542.75 | AC5: =(AB5*4018.41)/1000 -> 30309.862 | AD5: ='[1]AGO 29'!$AD$55 -> 5155 | AE5: =(AD5*4018.41)/1000 -> 20714.904 | AF5: ='[1]AGO 29'!$AF$55 -> 7956.87 | AG5: =(AF5*4018.41)/1000 -> 31973.966 | AH5: ='[1]AGO 29'!$AH$55 -> 282242.32 | AI5: =(AH5*4018.41)/1000 -> 1134165.4 | AJ5: ='[1]AGO 29'!$AJ$55 -> 675895.71 | AK5: =(AJ5*4018.41)/1000 -> 2716026.1 | AL5: ='[1]AGO 29'!$AL$55 -> 26171999 | AM5: ='[1]AGO 29'!$AM$55 -> 97180133 | AN5: ='[1]AGO 29'!$AN$55 -> 4862032.3 | AO5: ='[1]AGO 29'!$AO$55 -> 919690.75 | AP5: ='[1]AGO 29'!$AP$55 -> 10424918 | AQ5: ='[1]AGO 29'!$AQ$55 -> 1218366.3 | AR5: ='[1]AGO 29'!$AR$55 -> 33467.106 | AS5: ='[1]AGO 29'!$AS$55 -> 6.341908 | AT5: ='[1]AGO 29'!$AT$55 -> 11.326432 | AU5: ='[1]AGO 29'!$AU$55 -> 70852.565 | AV5: ='[1]AGO 29'!$AV$55 -> 529097.77 | AW5: ='[1]AGO 29'!$AW$55 -> 87470.534 | AX5: ='[1]AGO 29'!$AX$55 -> 1064.5961 | AY5: ='[1]AGO 29'!$AY$55 -> 181309.04 | AZ5: ='[1]AGO 29'!$AZ$55 -> 23756.924 | BA5: ='[1]AGO 29'!$BA$55 -> 205865.95 | BB5: ='[1]AGO 29'!$BB$55 -> 71290.186 | BC5: ='[1]AGO 29'!$BC$55 -> 271948.66 | BD5: ='[1]AGO 29'!$BD$55 -> 17375.684 | BE5: ='[1]AGO 29'!$BE$55 -> 256616.87 | BF5: ='[1]AGO 29'!$BF$55 -> 294814.04 | BG5: ='[1]AGO 29'!$BG$55 -> 35110.408 | BH5: ='[1]AGO 29'!$BH$55 -> 24605.161 | BI5: ='[1]AGO 29'!$BI$55 -> 207727.9 | BJ5: ='[1]AGO 29'!$BJ$55 -> 154010.6 | BK5: ='[1]AGO 29'!$BK$55 -> 4837922.1 | BL5: ='[1]AGO 29'!$BL$55 -> 114992.78 | BM5: ='[1]AGO 29'!$BM$55 -> 1090174.3 | BN5: ='[1]AGO 29'!$BN$55 -> 1242100.2 | BO5: ='[1]AGO 29'!$BO$55 -> 0.0034691202 | BP5: ='[1]AGO 29'!$BP$55 -> 260.7085 | BQ5: ='[1]AGO 29'!$BQ$55 -> 0.0040128799 | BR5: ='[1]AGO 29'!$BR$55 -> 358178.97 | BS5: ='[1]AGO 29'!$BS$55 -> 1439553.5 | BT5: ='[1]AGO 29'!$BT$55 -> 231922.66 | BU5: ='[1]AGO 29'!$BU$55 -> 932118.05 | BV5: ='[1]AGO 29'!$BV$55 -> 9460.5789 | BW5: ='[1]AGO 29'!$BW$55 -> 111247.72 | BX5: ='[1]AGO 29'!$BX$55 -> 22663.665 | BY5: ='[1]AGO 29'!$BY$55 -> 1110929.5 | BZ5: ='[1]AGO 29'!$BZ$55 -> -12760.021 | CA5: ='[1]AGO 29'!$CA$55 -> 7114722.5 | CB5: ='[1]AGO 29'!$CB$55 -> 19818.566 | CC5: ='[1]AGO 29'!$CC$55 -> 1067885.8 | CD5: ='[1]AGO 29'!$CD$55 -> 0 | CE5: ='[1]AGO 29'!$CE$55 -> 23629.153 | CF5: ='[1]AGO 29'!$CF$55 -> 719967.15 | CG5: ='[1]AGO 29'!$CG$55 -> 441343.13 | CH5: ='[1]AGO 29'!$CH$55 -> 2.93182 | CI5: ='[1]AGO 29'!$CI$55 -> 831592.3 | CJ5: ='[1]AGO 29'!$CJ$55 -> 528219.12 | CK5: ='[1]AGO 29'!$CK$55 -> 0 | CL5: ='[1]AGO 29'!$CL$55 -> 0 | CM5: ='[1]AGO 29'!$CM$55 -> 79545.207 | CN5: ='[1]AGO 29'!$CN$55 -> 647657.34 | CO5: ='[1]AGO 29'!$CO$55 -> 736464.84 | CP5: ='[1]AGO 29'!$CP$55 -> 9152723.7 | CQ5: ='[1]AGO 29'!$CQ$55 -> 377715.39 | CR5: ='[1]AGO 29'!$CR$55 -> 903266.84 | CS5: ='[1]AGO 29'!$CS$55 -> 5013.42 | CT5: ='[1]AGO 29'!$CT$55 -> 20149.388 | CU5: ='[1]AGO 29'!$CU$55 -> 5013.42 | CV5: ='[1]AGO 29'!$CV$55 -> 20149.388 | CW5: =D5+E5+F5+G5+H5+I5+J5+K5+L5+M5+O5+Q5+S5+U5+W5+Y5+AA5+AC5+AE5+AG5+AI5+AK5+AL5+AM5+AQ5+AR5+AS5+AT5+AU5+AV5+AW5+AX5+AY5+AZ5+BA5+BB5+BC5+BD5+BE5+BF5+BG5+BH5+BI5+BJ5+BK5+BS5+BU5+BV5+BW5+BX5+BY5+BZ5+CA5+CB5+CC5+CD5+CE5+CF5+CG5+CH5+CI5+CJ5+BL5+BM5+BN5+BO5+BP5+BQ5+CK5+CL5+CM5+CN5+CO5+CP5+CQ5+AN5+AO5+AP5+CR5+CT5+CV5 -> 3.6529439e+08
C6: CONSUMO | D6: -31253.949 | E6: 74335787 | F6: 5169790.9 | G6: 0 | H6: 0 | I6: 0 | J6: 0 | K6: 0 | L6: 0 | M6: 0 | N6: 0 | O6: 0 | P6: 0 | Q6: 0 | R6: 0 | S6: 0 | T6: 0 | U6: 0 | V6: 0 | W6: 0 | X6: 0 | Y6: 0 | Z6: 0 | AA6: 0 | AB6: 0 | AC6: 0 | AD6: 0 | AE6: 0 | AF6: 0 | AG6: 0 | AH6: 0 | AI6: 0 | AJ6: 0 | AK6: 0 | AL6: 0 | AM6: 0 | AN6: 0 | AO6: 0 | AP6: 0 | AQ6: 0 | AR6: 0 | AS6: 0 | AT6: 0 | AU6: 0 | AV6: 0 | AW6: 0 | AX6: 0 | AY6: 0 | AZ6: 0 | BA6: 0 | BB6: 0 | BC6: 0 | BD6: 0 | BE6: 0 | BF6: 0 | BG6: 0 | BH6: 0 | BI6: 0 | BJ6: 0 | BK6: 0 | BL6: 0 | BM6: 0 | BN6: 0 | BO6: 0 | BP6: 0 | BQ6: 0 | BR6: 0 | BS6: 0 | BT6: 0 | BU6: 0 | BV6: 0 | BW6: 0 | BX6: 0 | BY6: -18630.535 | BZ6: -10894956 | CA6: -3064839 | CB6: -0.00024 | CC6: 0 | CD6: 0 | CE6: 0 | CF6: 0 | CG6: 0 | CH6: 0 | CI6: 0 | CJ6: 0 | CK6: 0 | CL6: 0 | CM6: 0 | CN6: 0 | CO6: 0 | CP6: 0 | CQ6: 0 | CR6: 0 | CS6: 0 | CT6: 0 | CU6: 0 | CV6: 0
C7: VENTANILLA
C8: SALDO NETO INICIAL PAGADURÍA | D8: =D5+D6+D7 -> 433367.67 | E8: =E5+E6+E7 -> 81538452 | F8: =F5+F6+F7 -> 19561675 | G8: =G5+G6+G7 -> 0 | H8: =H5+H6+H7 -> 0 | I8: =I5+I6+I7 -> 74942.28 | J8: =J5+J6+J7 -> 0 | K8: =K5+K6+K7 -> 63079.012 | ... BX8: =BX5+BX6+BX7 -> 22663.665 | BY8: =+BY5+BY6+BY7:BZ7 -> 1092298.9 | BZ8: =BZ5+BZ6+BZ7 -> -10907716 | CA8: =CA5+CA6+CA7 -> 4049883.6 | CB8: =CB5+CB6+CB7 -> 19818.566 | CC8: =CC5+CC6+CC7 -> 1067885.8 | CD8: =CD5+CD6+CD7 -> 0 | CE8: =CE5+CE6+CE7 -> 23629.153 | CF8: =CF5+CF6+CF7 -> 719967.15 | CG8: =CG5+CG6+CG7 -> 441343.13 | ... CV8: =CV5+CV6+CV7 -> 20149.388 | CW8: =D8+E8+F8+G8+H8+I8+J8+K8+L8+M8+O8+Q8+S8+U8+W8+Y8+AA8+AC8+AE8+AG8+AI8+AK8+AL8+AM8+AQ8+AR8+AS8+AT8+AU8+AV8+AW8+AX8+AY8+AZ8+BA8+BB8+BC8+BD8+BE8+BF8+BG8+BH8+BI8+BJ8+BK8+BS8+BU8+BV8+BW8+BX8+BY8+BZ8+CA8+CB8+CC8+CD8+CE8+CF8+CG8+CH8+CI8+CJ8+BL8+BM8+BN8+BO8+BP8+BQ8+CK8+CL8+CM8+CN8+CO8+CP8+CQ8+AN8+AO8+AP8+CR8+CT8+CV8 -> 4.3079028e+08
A9: RENTA FIJA | B9: I | C9: PAGOS INTERCOMPAÑÍAS | CW9: =D9+E9+F9+G9+H9+I9+J9+K9+L9+M9+O9+Q9+S9+U9+W9+Y9+AA9+AC9+AE9+AG9+AI9+AK9+AL9+AM9+AQ9+AR9+AS9+AT9+AU9+AV9+AW9+AX9+AY9+AZ9+BA9+BB9+BC9+BD9+BE9+BF9+BG9+BH9+BI9+BJ9+BK9+BS9+BU9+BV9+BW9+BX9+BY9+BZ9+CA9+CB9+CC9+CD9+CE9+CF9+CG9+CH9+CI9+CJ9+BL9+BM9+BN9+BO9+BP9+BQ9+CK9+CL9+CM9+CN9+CO9+CP9+CQ9+AN9+AO9+AP9+CR9+CT9+CV9 -> 0
B10: E | C10: PAGOS INTERCOMPAÑÍAS | CW10: =D10+E10+F10+G10+H10+I10+J10+K10+L10+M10+O10+Q10+S10+U10+W10+Y10+AA10+AC10+AE10+AG10+AI10+AK10+AL10+AM10+AQ10+AR10+AS10+AT10+AU10+AV10+AW10+AX10+AY10+AZ10+BA10+BB10+BC10+BD10+BE10+BF10+BG10+BH10+BI10+BJ10+BK10+BS10+BU10+BV10+BW10+BX10+BY10+BZ10+CA10+CB10+CC10+CD10+CE10+CF10+CG10+CH10+CI10+CJ10+BL10+BM10+BN10+BO10+BP10+BQ10+CK10+CL10+CM10+CN10+CO10+CP10+CQ10+AN10+AO10+AP10+CR10+CT10+CV10 -> 0
B11: I | C11: INGRESOS INTERESES | L11: 283416 | M11: =96354+231270 -> 327624 | CW11: =D11+E11+F11+G11+H11+I11+J11+K11+L11+M11+O11+Q11+S11+U11+W11+Y11+AA11+AC11+AE11+AG11+AI11+AK11+AL11+AM11+AQ11+AR11+AS11+AT11+AU11+AV11+AW11+AX11+AY11+AZ11+BA11+BB11+BC11+BD11+BE11+BF11+BG11+BH11+BI11+BJ11+BK11+BS11+BU11+BV11+BW11+BX11+BY11+BZ11+CA11+CB11+CC11+CD11+CE11+CF11+CG11+CH11+CI11+CJ11+BL11+BM11+BN11+BO11+BP11+BQ11+CK11+CL11+CM11+CN11+CO11+CP11+CQ11+AN11+AO11+AP11+CR11+CT11+CV11 -> 611040
B12: I | C12: INGRESO REDENCIÓN TÍTULOS | CW12: =D12+E12+F12+G12+H12+I12+J12+K12+L12+M12+O12+Q12+S12+U12+W12+Y12+AA12+AC12+AE12+AG12+AI12+AK12+AL12+AM12+AQ12+AR12+AS12+AT12+AU12+AV12+AW12+AX12+AY12+AZ12+BA12+BB12+BC12+BD12+BE12+BF12+BG12+BH12+BI12+BJ12+BK12+BS12+BU12+BV12+BW12+BX12+BY12+BZ12+CA12+CB12+CC12+CD12+CE12+CF12+CG12+CH12+CI12+CJ12+BL12+BM12+BN12+BO12+BP12+BQ12+CK12+CL12+CM12+CN12+CO12+CP12+CQ12+AN12+AO12+AP12+CR12+CT12+CV12 -> 0
B13: E | C13: APERTURA ACTIVO FINANCIERO | CW13: =D13+E13+F13+G13+H13+I13+J13+K13+L13+M13+O13+Q13+S13+U13+W13+Y13+AA13+AC13+AE13+AG13+AI13+AK13+AL13+AM13+AQ13+AR13+AS13+AT13+AU13+AV13+AW13+AX13+AY13+AZ13+BA13+BB13+BC13+BD13+BE13+BF13+BG13+BH13+BI13+BJ13+BK13+BS13+BU13+BV13+BW13+BX13+BY13+BZ13+CA13+CB13+CC13+CD13+CE13+CF13+CG13+CH13+CI13+CJ13+BL13+BM13+BN13+BO13+BP13+BQ13+CK13+CL13+CM13+CN13+CO13+CP13+CQ13+AN13+AO13+AP13+CR13+CT13+CV13 -> 0
B14: I | C14: CANCELACIÓN ACTIVO FINANCIERO | CW14: =D14+E14+F14+G14+H14+I14+J14+K14+L14+M14+O14+Q14+S14+U14+W14+Y14+AA14+AC14+AE14+AG14+AI14+AK14+AL14+AM14+AQ14+AR14+AS14+AT14+AU14+AV14+AW14+AX14+AY14+AZ14+BA14+BB14+BC14+BD14+BE14+BF14+BG14+BH14+BI14+BJ14+BK14+BS14+BU14+BV14+BW14+BX14+BY14+BZ14+CA14+CB14+CC14+CD14+CE14+CF14+CG14+CH14+CI14+CJ14+BL14+BM14+BN14+BO14+BP14+BQ14+CK14+CL14+CM14+CN14+CO14+CP14+CQ14+AN14+AO14+AP14+CR14+CT14+CV14 -> 0
B15: I | C15: INTERESES ACTIVO FINANCIERO | CW15: =D15+E15+F15+G15+H15+I15+J15+K15+L15+M15+O15+Q15+S15+U15+W15+Y15+AA15+AC15+AE15+AG15+AI15+AK15+AL15+AM15+AQ15+AR15+AS15+AT15+AU15+AV15+AW15+AX15+AY15+AZ15+BA15+BB15+BC15+BD15+BE15+BF15+BG15+BH15+BI15+BJ15+BK15+BS15+BU15+BV15+BW15+BX15+BY15+BZ15+CA15+CB15+CC15+CD15+CE15+CF15+CG15+CH15+CI15+CJ15+BL15+BM15+BN15+BO15+BP15+BQ15+CK15+CL15+CM15+CN15+CO15+CP15+CQ15+AN15+AO15+AP15+CR15+CT15+CV15 -> 0
B16: E | C16: CANCELACIÓN KW | CW16: =D16+E16+F16+G16+H16+I16+J16+K16+L16+M16+O16+Q16+S16+U16+W16+Y16+AA16+AC16+AE16+AG16+AI16+AK16+AL16+AM16+AQ16+AR16+AS16+AT16+AU16+AV16+AW16+AX16+AY16+AZ16+BA16+BB16+BC16+BD16+BE16+BF16+BG16+BH16+BI16+BJ16+BK16+BS16+BU16+BV16+BW16+BX16+BY16+BZ16+CA16+CB16+CC16+CD16+CE16+CF16+CG16+CH16+CI16+CJ16+BL16+BM16+BN16+BO16+BP16+BQ16+CK16+CL16+CM16+CN16+CO16+CP16+CQ16+AN16+AO16+AP16+CR16+CT16+CV16 -> 0
B17: E | C17: PAGO INTERESES KW | CW17: =D17+E17+F17+G17+H17+I17+J17+K17+L17+M17+O17+Q17+S17+U17+W17+Y17+AA17+AC17+AE17+AG17+AI17+AK17+AL17+AM17+AQ17+AR17+AS17+AT17+AU17+AV17+AW17+AX17+AY17+AZ17+BA17+BB17+BC17+BD17+BE17+BF17+BG17+BH17+BI17+BJ17+BK17+BS17+BU17+BV17+BW17+BX17+BY17+BZ17+CA17+CB17+CC17+CD17+CE17+CF17+CG17+CH17+CI17+CJ17+BL17+BM17+BN17+BO17+BP17+BQ17+CK17+CL17+CM17+CN17+CO17+CP17+CQ17+AN17+AO17+AP17+CR17+CT17+CV17 -> 0
B18: I | C18: APERTURA KW | CW18: =D18+E18+F18+G18+H18+I18+J18+K18+L18+M18+O18+Q18+S18+U18+W18+Y18+AA18+AC18+AE18+AG18+AI18+AK18+AL18+AM18+AQ18+AR18+AS18+AT18+AU18+AV18+AW18+AX18+AY18+AZ18+BA18+BB18+BC18+BD18+BE18+BF18+BG18+BH18+BI18+BJ18+BK18+BS18+BU18+BV18+BW18+BX18+BY18+BZ18+CA18+CB18+CC18+CD18+CE18+CF18+CG18+CH18+CI18+CJ18+BL18+BM18+BN18+BO18+BP18+BQ18+CK18+CL18+CM18+CN18+CO18+CP18+CQ18+AN18+AO18+AP18+CR18+CT18+CV18 -> 0
B19: E | C19: COMPRA TÍTULOS | CW19: =D19+E19+F19+G19+H19+I19+J19+K19+L19+M19+O19+Q19+S19+U19+W19+Y19+AA19+AC19+AE19+AG19+AI19+AK19+AL19+AM19+AQ19+AR19+AS19+AT19+AU19+AV19+AW19+AX19+AY19+AZ19+BA19+BB19+BC19+BD19+BE19+BF19+BG19+BH19+BI19+BJ19+BK19+BS19+BU19+BV19+BW19+BX19+BY19+BZ19+CA19+CB19+CC19+CD19+CE19+CF19+CG19+CH19+CI19+CJ19+BL19+BM19+BN19+BO19+BP19+BQ19+CK19+CL19+CM19+CN19+CO19+CP19+CQ19+AN19+AO19+AP19+CR19+CT19+CV19 -> 0
B20: E | C20: COMPRA SIMULTÁNEA ACTIVA | L20: -8143610.4 | M20: -12063579 | CW20: =D20+E20+F20+G20+H20+I20+J20+K20+L20+M20+O20+Q20+S20+U20+W20+Y20+AA20+AC20+AE20+AG20+AI20+AK20+AL20+AM20+AQ20+AR20+AS20+AT20+AU20+AV20+AW20+AX20+AY20+AZ20+BA20+BB20+BC20+BD20+BE20+BF20+BG20+BH20+BI20+BJ20+BK20+BS20+BU20+BV20+BW20+BX20+BY20+BZ20+CA20+CB20+CC20+CD20+CE20+CF20+CG20+CH20+CI20+CJ20+BL20+BM20+BN20+BO20+BP20+BQ20+CK20+CL20+CM20+CN20+CO20+CP20+CQ20+AN20+AO20+AP20+CR20+CT20+CV20 -> -20207190
B21: E | C21: REDENCIÓN SIMULTÁNEA PASIVA | L21: -1.0689144e+08 | CW21: =D21+E21+F21+G21+H21+I21+J21+K21+L21+M21+O21+Q21+S21+U21+W21+Y21+AA21+AC21+AE21+AG21+AI21+AK21+AL21+AM21+AQ21+AR21+AS21+AT21+AU21+AV21+AW21+AX21+AY21+AZ21+BA21+BB21+BC21+BD21+BE21+BF21+BG21+BH21+BI21+BJ21+BK21+BS21+BU21+BV21+BW21+BX21+BY21+BZ21+CA21+CB21+CC21+CD21+CE21+CF21+CG21+CH21+CI21+CJ21+BL21+BM21+BN21+BO21+BP21+BQ21+CK21+CL21+CM21+CN21+CO21+CP21+CQ21+AN21+AO21+AP21+CR21+CT21+CV21 -> -1.0689144e+08
B22: I | C22: VENTA TÍTULOS | L22: 4254235 | CW22: =D22+E22+F22+G22+H22+I22+J22+K22+L22+M22+O22+Q22+S22+U22+W22+Y22+AA22+AC22+AE22+AG22+AI22+AK22+AL22+AM22+AQ22+AR22+AS22+AT22+AU22+AV22+AW22+AX22+AY22+AZ22+BA22+BB22+BC22+BD22+BE22+BF22+BG22+BH22+BI22+BJ22+BK22+BS22+BU22+BV22+BW22+BX22+BY22+BZ22+CA22+CB22+CC22+CD22+CE22+CF22+CG22+CH22+CI22+CJ22+BL22+BM22+BN22+BO22+BP22+BQ22+CK22+CL22+CM22+CN22+CO22+CP22+CQ22+AN22+AO22+AP22+CR22+CT22+CV22 -> 4254235
B23: I | C23: COMPRA SIMULTÁNEA PASIVA | L23: 1.5219701e+08 | CW23: =D23+E23+F23+G23+H23+I23+J23+K23+L23+M23+O23+Q23+S23+U23+W23+Y23+AA23+AC23+AE23+AG23+AI23+AK23+AL23+AM23+AQ23+AR23+AS23+AT23+AU23+AV23+AW23+AX23+AY23+AZ23+BA23+BB23+BC23+BD23+BE23+BF23+BG23+BH23+BI23+BJ23+BK23+BS23+BU23+BV23+BW23+BX23+BY23+BZ23+CA23+CB23+CC23+CD23+CE23+CF23+CG23+CH23+CI23+CJ23+BL23+BM23+BN23+BO23+BP23+BQ23+CK23+CL23+CM23+CN23+CO23+CP23+CQ23+AN23+AO23+AP23+CR23+CT23+CV23 -> 1.5219701e+08
B24: I | C24: REDENCIÓN SIMULTÁNEA ACTIVA | CW24: =D24+E24+F24+G24+H24+I24+J24+K24+L24+M24+O24+Q24+S24+U24+W24+Y24+AA24+AC24+AE24+AG24+AI24+AK24+AL24+AM24+AQ24+AR24+AS24+AT24+AU24+AV24+AW24+AX24+AY24+AZ24+BA24+BB24+BC24+BD24+BE24+BF24+BG24+BH24+BI24+BJ24+BK24+BS24+BU24+BV24+BW24+BX24+BY24+BZ24+CA24+CB24+CC24+CD24+CE24+CF24+CG24+CH24+CI24+CJ24+BL24+BM24+BN24+BO24+BP24+BQ24+CK24+CL24+CM24+CN24+CO24+CP24+CQ24+AN24+AO24+AP24+CR24+CT24+CV24 -> 0
B25: I | C25: DISTRIBUCIÓN FCP | CW25: =D25+E25+F25+G25+H25+I25+J25+K25+L25+M25+O25+Q25+S25+U25+W25+Y25+AA25+AC25+AE25+AG25+AI25+AK25+AL25+AM25+AQ25+AR25+AS25+AT25+AU25+AV25+AW25+AX25+AY25+AZ25+BA25+BB25+BC25+BD25+BE25+BF25+BG25+BH25+BI25+BJ25+BK25+BS25+BU25+BV25+BW25+BX25+BY25+BZ25+CA25+CB25+CC25+CD25+CE25+CF25+CG25+CH25+CI25+CJ25+BL25+BM25+BN25+BO25+BP25+BQ25+CK25+CL25+CM25+CN25+CO25+CP25+CQ25+AN25+AO25+AP25+CR25+CT25+CV25 -> 0
B26: E | C26: LLAMADO CAPITAL FCP | CW26: =D26+E26+F26+G26+H26+I26+J26+K26+L26+M26+O26+Q26+S26+U26+W26+Y26+AA26+AC26+AE26+AG26+AI26+AK26+AL26+AM26+AQ26+AR26+AS26+AT26+AU26+AV26+AW26+AX26+AY26+AZ26+BA26+BB26+BC26+BD26+BE26+BF26+BG26+BH26+BI26+BJ26+BK26+BS26+BU26+BV26+BW26+BX26+BY26+BZ26+CA26+CB26+CC26+CD26+CE26+CF26+CG26+CH26+CI26+CJ26+BL26+BM26+BN26+BO26+BP26+BQ26+CK26+CL26+CM26+CN26+CO26+CP26+CQ26+AN26+AO26+AP26+CR26+CT26+CV26 -> 0
B27: I | C27: RETIRO DE CAPITAL ENCARGOS | E27: 5000000 | BZ27: 10800000 | CW27: =D27+E27+F27+G27+H27+I27+J27+K27+L27+M27+O27+Q27+S27+U27+W27+Y27+AA27+AC27+AE27+AG27+AI27+AK27+AL27+AM27+AQ27+AR27+AS27+AT27+AU27+AV27+AW27+AX27+AY27+AZ27+BA27+BB27+BC27+BD27+BE27+BF27+BG27+BH27+BI27+BJ27+BK27+BS27+BU27+BV27+BW27+BX27+BY27+BZ27+CA27+CB27+CC27+CD27+CE27+CF27+CG27+CH27+CI27+CJ27+BL27+BM27+BN27+BO27+BP27+BQ27+CK27+CL27+CM27+CN27+CO27+CP27+CQ27+AN27+AO27+AP27+CR27+CT27+CV27 -> 15800000
B28: E | C28: INCREMENTO DE CAPITAL ENCARGOS | D28: -15000 | L28: -22450000 | CW28: =D28+E28+F28+G28+H28+I28+J28+K28+L28+M28+O28+Q28+S28+U28+W28+Y28+AA28+AC28+AE28+AG28+AI28+AK28+AL28+AM28+AQ28+AR28+AS28+AT28+AU28+AV28+AW28+AX28+AY28+AZ28+BA28+BB28+BC28+BD28+BE28+BF28+BG28+BH28+BI28+BJ28+BK28+BS28+BU28+BV28+BW28+BX28+BY28+BZ28+CA28+CB28+CC28+CD28+CE28+CF28+CG28+CH28+CI28+CJ28+BL28+BM28+BN28+BO28+BP28+BQ28+CK28+CL28+CM28+CN28+CO28+CP28+CQ28+AN28+AO28+AP28+CR28+CT28+CV28 -> -22465000
C29: TRASLADO ARL | E29: 15801000 | F29: =-12870000+12870000-12870000 -> -12870000 | L29: -15801000 | M29: 12870000 | CW29: =D29+E29+F29+G29+H29+I29+J29+K29+L29+M29+O29+Q29+S29+U29+W29+Y29+AA29+AC29+AE29+AG29+AI29+AK29+AL29+AM29+AQ29+AR29+AS29+AT29+AU29+AV29+AW29+AX29+AY29+AZ29+BA29+BB29+BC29+BD29+BE29+BF29+BG29+BH29+BI29+BJ29+BK29+BS29+BU29+BV29+BW29+BX29+BY29+BZ29+CA29+CB29+CC29+CD29+CE29+CF29+CG29+CH29+CI29+CJ29+BL29+BM29+BN29+BO29+BP29+BQ29+CK29+CL29+CM29+CN29+CO29+CP29+CQ29+AN29+AO29+AP29+CR29+CT29+CV29 -> 0
A30: RENTA VARIABLE | B30: E | C30: COMPRA ACCIONES | CW30: =D30+E30+F30+G30+H30+I30+J30+K30+L30+M30+O30+Q30+S30+U30+W30+Y30+AA30+AC30+AE30+AG30+AI30+AK30+AL30+AM30+AQ30+AR30+AS30+AT30+AU30+AV30+AW30+AX30+AY30+AZ30+BA30+BB30+BC30+BD30+BE30+BF30+BG30+BH30+BI30+BJ30+BK30+BS30+BU30+BV30+BW30+BX30+BY30+BZ30+CA30+CB30+CC30+CD30+CE30+CF30+CG30+CH30+CI30+CJ30+BL30+BM30+BN30+BO30+BP30+BQ30+CK30+CL30+CM30+CN30+CO30+CP30+CQ30+AN30+AO30+AP30+CR30+CT30+CV30 -> 0
B31: I | C31: VENTA ACCIONES | L31: 213919.1 | CW31: =D31+E31+F31+G31+H31+I31+J31+K31+L31+M31+O31+Q31+S31+U31+W31+Y31+AA31+AC31+AE31+AG31+AI31+AK31+AL31+AM31+AQ31+AR31+AS31+AT31+AU31+AV31+AW31+AX31+AY31+AZ31+BA31+BB31+BC31+BD31+BE31+BF31+BG31+BH31+BI31+BJ31+BK31+BS31+BU31+BV31+BW31+BX31+BY31+BZ31+CA31+CB31+CC31+CD31+CE31+CF31+CG31+CH31+CI31+CJ31+BL31+BM31+BN31+BO31+BP31+BQ31+CK31+CL31+CM31+CN31+CO31+CP31+CQ31+AN31+AO31+AP31+CR31+CT31+CV31 -> 213919.1
B32: I | C32: INGRESO DIVIDENDOS | CW32: =D32+E32+F32+G32+H32+I32+J32+K32+L32+M32+O32+Q32+S32+U32+W32+Y32+AA32+AC32+AE32+AG32+AI32+AK32+AL32+AM32+AQ32+AR32+AS32+AT32+AU32+AV32+AW32+AX32+AY32+AZ32+BA32+BB32+BC32+BD32+BE32+BF32+BG32+BH32+BI32+BJ32+BK32+BS32+BU32+BV32+BW32+BX32+BY32+BZ32+CA32+CB32+CC32+CD32+CE32+CF32+CG32+CH32+CI32+CJ32+BL32+BM32+BN32+BO32+BP32+BQ32+CK32+CL32+CM32+CN32+CO32+CP32+CQ32+AN32+AO32+AP32+CR32+CT32+CV32 -> 0
B33: E | C33: EGRESO DIVIDENDOS | CW33: =D33+E33+F33+G33+H33+I33+J33+K33+L33+M33+O33+Q33+S33+U33+W33+Y33+AA33+AC33+AE33+AG33+AI33+AK33+AL33+AM33+AQ33+AR33+AS33+AT33+AU33+AV33+AW33+AX33+AY33+AZ33+BA33+BB33+BC33+BD33+BE33+BF33+BG33+BH33+BI33+BJ33+BK33+BS33+BU33+BV33+BW33+BX33+BY33+BZ33+CA33+CB33+CC33+CD33+CE33+CF33+CG33+CH33+CI33+CJ33+BL33+BM33+BN33+BO33+BP33+BQ33+CK33+CL33+CM33+CN33+CO33+CP33+CQ33+AN33+AO33+AP33+CR33+CT33+CV33 -> 0
B34: I | C34: INGRESO DIVIDENDOS ETF | CW34: =D34+E34+F34+G34+H34+I34+J34+K34+L34+M34+O34+Q34+S34+U34+W34+Y34+AA34+AC34+AE34+AG34+AI34+AK34+AL34+AM34+AQ34+AR34+AS34+AT34+AU34+AV34+AW34+AX34+AY34+AZ34+BA34+BB34+BC34+BD34+BE34+BF34+BG34+BH34+BI34+BJ34+BK34+BS34+BU34+BV34+BW34+BX34+BY34+BZ34+CA34+CB34+CC34+CD34+CE34+CF34+CG34+CH34+CI34+CJ34+BL34+BM34+BN34+BO34+BP34+BQ34+CK34+CL34+CM34+CN34+CO34+CP34+CQ34+AN34+AO34+AP34+CR34+CT34+CV34 -> 0
A35: DERIVADOS | C35: SWAP | CW35: =D35+E35+F35+G35+H35+I35+J35+K35+L35+M35+O35+Q35+S35+U35+W35+Y35+AA35+AC35+AE35+AG35+AI35+AK35+AL35+AM35+AQ35+AR35+AS35+AT35+AU35+AV35+AW35+AX35+AY35+AZ35+BA35+BB35+BC35+BD35+BE35+BF35+BG35+BH35+BI35+BJ35+BK35+BS35+BU35+BV35+BW35+BX35+BY35+BZ35+CA35+CB35+CC35+CD35+CE35+CF35+CG35+CH35+CI35+CJ35+BL35+BM35+BN35+BO35+BP35+BQ35+CK35+CL35+CM35+CN35+CO35+CP35+CQ35+AN35+AO35+AP35+CR35+CT35+CV35 -> 0
B36: E | C36: OPCIONES | CW36: =D36+E36+F36+G36+H36+I36+J36+K36+L36+M36+O36+Q36+S36+U36+W36+Y36+AA36+AC36+AE36+AG36+AI36+AK36+AL36+AM36+AQ36+AR36+AS36+AT36+AU36+AV36+AW36+AX36+AY36+AZ36+BA36+BB36+BC36+BD36+BE36+BF36+BG36+BH36+BI36+BJ36+BK36+BS36+BU36+BV36+BW36+BX36+BY36+BZ36+CA36+CB36+CC36+CD36+CE36+CF36+CG36+CH36+CI36+CJ36+BL36+BM36+BN36+BO36+BP36+BQ36+CK36+CL36+CM36+CN36+CO36+CP36+CQ36+AN36+AO36+AP36+CR36+CT36+CV36 -> 0
B37: I | C37: OPCIONES | CW37: =D37+E37+F37+G37+H37+I37+J37+K37+L37+M37+O37+Q37+S37+U37+W37+Y37+AA37+AC37+AE37+AG37+AI37+AK37+AL37+AM37+AQ37+AR37+AS37+AT37+AU37+AV37+AW37+AX37+AY37+AZ37+BA37+BB37+BC37+BD37+BE37+BF37+BG37+BH37+BI37+BJ37+BK37+BS37+BU37+BV37+BW37+BX37+BY37+BZ37+CA37+CB37+CC37+CD37+CE37+CF37+CG37+CH37+CI37+CJ37+BL37+BM37+BN37+BO37+BP37+BQ37+CK37+CL37+CM37+CN37+CO37+CP37+CQ37+AN37+AO37+AP37+CR37+CT37+CV37 -> 0
B38: E | C38: FORWARD | L38: =-796900-1186080-1799280 -> -3782260 | M38: =-318760-478140-199920 -> -996820 | CW38: =D38+E38+F38+G38+H38+I38+J38+K38+L38+M38+O38+Q38+S38+U38+W38+Y38+AA38+AC38+AE38+AG38+AI38+AK38+AL38+AM38+AQ38+AR38+AS38+AT38+AU38+AV38+AW38+AX38+AY38+AZ38+BA38+BB38+BC38+BD38+BE38+BF38+BG38+BH38+BI38+BJ38+BK38+BS38+BU38+BV38+BW38+BX38+BY38+BZ38+CA38+CB38+CC38+CD38+CE38+CF38+CG38+CH38+CI38+CJ38+BL38+BM38+BN38+BO38+BP38+BQ38+CK38+CL38+CM38+CN38+CO38+CP38+CQ38+AN38+AO38+AP38+CR38+CT38+CV38 -> -4779080
B39: I | C39: FORWARD | CW39: =D39+E39+F39+G39+H39+I39+J39+K39+L39+M39+O39+Q39+S39+U39+W39+Y39+AA39+AC39+AE39+AG39+AI39+AK39+AL39+AM39+AQ39+AR39+AS39+AT39+AU39+AV39+AW39+AX39+AY39+AZ39+BA39+BB39+BC39+BD39+BE39+BF39+BG39+BH39+BI39+BJ39+BK39+BS39+BU39+BV39+BW39+BX39+BY39+BZ39+CA39+CB39+CC39+CD39+CE39+CF39+CG39+CH39+CI39+CJ39+BL39+BM39+BN39+BO39+BP39+BQ39+CK39+CL39+CM39+CN39+CO39+CP39+CQ39+AN39+AO39+AP39+CR39+CT39+CV39 -> 0
A40: DIVISAS | B40: E | C40: COMPRA DIVISAS OTRAS ÁREAS | CW40: =D40+E40+F40+G40+H40+I40+J40+K40+L40+M40+O40+Q40+S40+U40+W40+Y40+AA40+AC40+AE40+AG40+AI40+AK40+AL40+AM40+AQ40+AR40+AS40+AT40+AU40+AV40+AW40+AX40+AY40+AZ40+BA40+BB40+BC40+BD40+BE40+BF40+BG40+BH40+BI40+BJ40+BK40+BS40+BU40+BV40+BW40+BX40+BY40+BZ40+CA40+CB40+CC40+CD40+CE40+CF40+CG40+CH40+CI40+CJ40+BL40+BM40+BN40+BO40+BP40+BQ40+CK40+CL40+CM40+CN40+CO40+CP40+CQ40+AN40+AO40+AP40+CR40+CT40+CV40 -> 0
...

Sheet SEP 02
D1: OPERACIONES DE TESORERÍA | BL1: LIBRE INVERSION | BO1: FIC LIFE USD | BP1: FIC VIDA PESOS | BQ1: FIC LATIN VIDA PESOS | BR1: PAGADURÍA
D2: CAPITALIZADORA | E2: SEGUROS BOLÍVAR | F2: COMERCIALES | G2: CAPITALIZADORA AHO | H2: SEGUROS BOLÍVAR AHO | I2: SEGUROS BOLÍVAR ARL | J2: COMERCIALES AHO | K2: CAPITALIZADORA | L2: SEGUROS BOLÍVAR | M2: COMERCIALES | N2: CAPITALIZADORA US$ | O2: CAPITALIZADORA PESOS | P2: SEGUROS BOLÍVAR US$ | Q2: SEGUROS BOLÍVAR PESOS | R2: COMERCIALES US$ | S2: COMERCIALES PESOS | T2: CAPITALIZADORA US$ | U2: CAPITALIZADORA PESOS | V2: SEGUROS BOLÍVAR US$ | W2: SEGUROS BOLÍVAR PESOS | X2: COMERCIALES US$ | Y2: COMERCIALES PESOS | Z2: CAPITALIZADORA US$ | AA2: CAPITALIZADORA PESOS | AB2: SEGUROS BOLÍVAR US$ | AC2: SEGUROS BOLÍVAR PESOS | AD2: COMERCIALES US$ | AE2: COMERCIALES PESOS | AF2: GRUPO BOLIVAR US$ | AG2: GRUPO BOLIVAR PESOS | AH2: SEISA US$ | AI2: SEISA PESOS | AJ2: RIBI US$ | AK2: RIBI PESOS | AL2: GRUPO BOLIVAR | AM2: INVERSORAS | AN2: SALUD EPS BOLIVAR | AO2: SALUD IPS BOLIVAR | AP2: SERVICIOS BOLIVAR | AQ2: SERVICIOS BOLIVAR | AR2: CAPITALIZADORA | AS2: SEGUROS BOLÍVAR | AT2: SEGUROS BOLÍVAR ARL | AU2: COMERCIALES | AV2: GRUPO BOLIVAR | AW2: CAPITALIZADORA | AX2: SEGUROS BOLÍVAR | AY2: COMERCIALES | AZ2: GRUPO BOLIVAR | BA2: CAPITALIZADORA | BB2: SEGUROS BOLÍVAR | BC2: SEGUROS BOLÍVAR ARL | BD2: COMERCIALES | BE2: CAPITALIZADORA | BF2: SEGUROS BOLÍVAR | BG2: COMERCIALES | BH2: CAPITALIZADORA | BI2: SEGUROS BOLÍVAR | BJ2: COMERCIALES | BK2: GRUPO BOLIVAR | BL2: CAPITALIZADORA AHO | BM2: SEGUROS BOLÍVAR AHO | BN2: COMERCIALES AHO | BO2: SEGUROS BOLÍVAR AHO | BP2: SEGUROS BOLÍVAR AHO | BQ2: SEGUROS BOLÍVAR AHO | BR2: SEGUROS BOLÍVAR USD | BS2: SEGUROS BOLÍVAR PESOS | BT2: COMERCIALES USD | BU2: COMERCIALES PESOS | BV2: CAPITALIZADORA | BW2: SEGUROS BOLÍVAR | BX2: COMERCIALES | BY2: CAPITALIZADORA | BZ2: SEGUROS BOLÍVAR | CA2: COMERCIALES | CB2: CAPITALIZADORA | CC2: SEGUROS BOLÍVAR | CD2: COMERCIALES | CE2: CAPITALIZADORA | CF2: SEGUROS BOLÍVAR | CG2: COMERCIALES | CH2: COMERCIALES | CI2: SEGUROS BOLÍVAR | CJ2: COMERCIALES | CK2: SEGUROS BOLÍVAR | CL2: SEGUROS BOLÍVAR | CM2: SEGUROS BOLÍVAR | CN2: SEGUROS BOLÍVAR | CO2: SEGUROS BOLÍVAR | CP2: SEGUROS BOLÍVAR | CQ2: SEGUROS BOLÍVAR | CR2: SEGUROS BOLÍVAR | CS2: SEGUROS BOLÍVAR USD | CT2: SEGUROS BOLÍVAR PESOS | CU2: COMERCIALES USD | CV2: COMERCIALES PESOS | CW2: TOTALES
D3: BANCO DAVIVIENDA | E3: BANCO DAVIVIENDA | F3: BANCO DAVIVIENDA | G3: BANCO DAVIVIENDA | H3: BANCO DAVIVIENDA | I3: BANCO DAVIVIENDA | J3: BANCO DAVIVIENDA | K3: BANCO REPUBLICA | L3: BANCO REPUBLICA | M3: BANCO REPUBLICA | N3: CITIBANK COMP | O3: CITIBANK COMP | P3: CITIBANK COMP | Q3: CITIBANK COMP | R3: CITIBANK COMP | S3: CITIBANK COMP | T3: JP MORGAN | U3: JP MORGAN | V3: JP MORGAN | W3: JP MORGAN | X3: JP MORGAN | Y3: JP MORGAN | Z3: DAVIVIENDA INT | AA3: DAVIVIENDA INT | AB3: DAVIVIENDA INT | AC3: DAVIVIENDA INT | AD3: DAVIVIENDA INT | AE3: DAVIVIENDA INT | AF3: DAVIVIENDA INT | AG3: DAVIVIENDA INT | AH3: DAVIVIENDA INT | AI3: DAVIVIENDA INT | AJ3: DAVIVIENDA INT | AK3: DAVIVIENDA INT | AL3: DAVIVIENDA | AM3: DAVIVIENDA | AQ3: FACILITIES | AR3: BANCO DE BOGOTA | AS3: BANCO DE BOGOTA | AT3: BANCO DE BOGOTA | AU3: BANCO DE BOGOTA | AV3: BANCO DE BOGOTA | AW3: ITAÚ | AX3: ITAÚ | AY3: ITAÚ | AZ3: ITAÚ | BA3: CORFIDIARIO | BB3: CORFIDIARIO | BC3: CORFIDIARIO | BD3: CORFIDIARIO | BE3: BANCO COLPATRIA | BF3: BANCO COLPATRIA | BG3: BANCO COLPATRIA | BH3: BANCOLOMBIA | BI3: BANCOLOMBIA | BJ3: BANCOLOMBIA | BK3: BANCOLOMBIA | BL3: BANCO DAVIVIENDA | BM3: BANCO DAVIVIENDA | BN3: BANCO DAVIVIENDA | BO3: BANCO DAVIVIENDA | BP3: BANCO DAVIVIENDA | BQ3: BANCO DAVIVIENDA | BR3: CITIBANK REASEGUROS | BS3: CITIBANK REASEGUROS | BT3: CITIBANK REASEGUROS | BU3: CITIBANK REASEGUROS | BV3: BANCO DE BOGOTA | BW3: BANCO DE BOGOTA | BX3: BANCO DE BOGOTA | BY3: BANCOLOMBIA | BZ3: BANCOLOMBIA | CA3: BANCOLOMBIA | CB3: BANCO POPULAR | CC3: BANCO POPULAR | CD3: BANCO POPULAR | CE3: BBVA | CF3: BBVA | CG3: BBVA | CH3: BANCO COLPATRIA | CI3: BANCO DE OCCIDENTE | CJ3: BANCO DE OCCIDENTE | CK3: CITIBANK | CL3: CITIBANK | CM3: BANCO DAVIVIENDA | CN3: BANCOLOMBIA | CO3: AV VILLAS - AHO | CP3: BANCO DE OCCIDENTE | CQ3: BANCO DE OCCIDENTE | CR3: BANCO PICHINCHA | CS3: DAVIVIENDA INT REASEGUROS | CT3: DAVIVIENDA INT REASEGUROS | CU3: DAVIVIENDA INT REASEGUROS | CV3: DAVIVIENDA INT REASEGUROS
A4: TIPO OP | B4: OP | C4: CONCEPTO | G4: 482800001265 | H4: 482800001273 | I4: 482800002024 | J4: 482800001257 | K4: 62250766-0 | L4: 62250774-0 | M4: 62250782-0 | N4: 36203301 | O4: 36203301 | P4: 36203328 | Q4: 36203328 | R4: 36025015 | S4: 36025015 | T4: 705329517 | U4: 705329517 | V4: 705300062 | W4: 705300062 | X4: 705300070 | Y4: 705300070 | Z4: 865784010 | AA4: 865784010 | AB4: 865804010 | AC4: 865804010 | AD4: 865794010 | AE4: 865794010 | AF4: 867614010 | AG4: 867614010 | AH4: 010002000127 | AI4: 010002000127 | AJ4: 010003000003 | AK4: 010003000003 | AR4: 000977298 | AS4: 000268649 | AT4: 000977280 | AU4: 000977272 | AV4: 000826701 | AW4: 005597176 | AX4: 005595639 | AY4: 005597183 | AZ4: 005595646 | BA4: 2113700 | BB4: 2114920 | BC4: 2113692 | BD4: 2113718 | BE4: 0172120172 | BF4: 0172120180 | BG4: 0172120199 | BH4: 17171123071 | BI4: 17171122902 | BJ4: 17171123003 | BK4: ´03199361537 | BL4: 482800007882 | BM4: 482800007908 | BN4: 482800007890 | BO4: 482800010001 | BP4: 482800010019 | BQ4: 482800010027 | BR4: 36024995 | BS4: 36024995 | BT4: 36903922 | BU4: 36903922 | BV4: 036273662 | BW4: 036297810 | BX4: 036273688 | BY4: 5300635932 | BZ4: 5300250331 | CA4: 5300218006 | CB4: 40195224 | CC4: 40298119 | CD4: 40299661 | CE4: 137017554 | CF4: 137008629 | CG4: 137017562 | CH4: 121010607 | CI4: 221816614 | CJ4: 221816598 | CK4: 60193029 | CL4: 60193401 | CM4: 1011143807 | CN4: 4801736642 | CO4: 65005340 | CP4: 288086051 | CQ4: 288049109 | CR4: 411166042 | CS4: 865804015 | CT4: 865804015 | CU4: 865794015 | CV4: 865794015
A5: PAGADURÍA | C5: SALDO INICIAL | D5: ='SEP 01'!D55 -> 418367.67 | E5: ='SEP 01'!E55 -> 1.0233736e+08 | F5: ='SEP 01'!F55 -> 6691543 | G5: ='SEP 01'!G55 -> 0 | H5: ='SEP 01'!H55 -> 0 | I5: ='SEP 01'!I55 -> 74955.182 | J5: ='SEP 01'!J55 -> 0 | K5: ='SEP 01'!K55 -> 62362.027 | ... CV5: ='SEP 01'!CV55 -> 20149.388 | CW5: =D5+E5+F5+G5+H5+I5+J5+K5+L5+M5+O5+Q5+S5+U5+W5+Y5+AA5+AC5+AE5+AG5+AI5+AK5+AL5+AM5+AQ5+AR5+AS5+AT5+AU5+AV5+AW5+AX5+AY5+AZ5+BA5+BB5+BC5+BD5+BE5+BF5+BG5+BH5+BI5+BJ5+BK5+BS5+BU5+BV5+BW5+BX5+BY5+BZ5+CA5+CB5+CC5+CD5+CE5+CF5+CG5+CH5+CI5+CJ5+BL5+BM5+BN5+BO5+BP5+BQ5+CK5+CL5+CM5+CN5+CO5+CP5+CQ5+AN5+AO5+AP5+CR5+CT5+CV5 -> 4.4950068e+08
C6: CONSUMO | D6: -34988.446 | E6: 3432014.4 | F6: 1389291.3 | G6: 0 | H6: 0 | I6: 0 | J6: 0 | K6: 0 | L6: 0 | M6: 0 | N6: 0 | O6: 0 | P6: 0 | Q6: 0 | R6: 0 | S6: 0 | T6: 0 | U6: 0 | V6: 0 | W6: 0 | X6: 0 | Y6: 0 | Z6: 0 | AA6: 0 | AB6: 0 | AC6: 0 | AD6: 0 | AE6: 0 | AF6: 0 | AG6: 0 | AH6: 0 | AI6: 0 | AJ6: 0 | AK6: 0 | AL6: 0 | AM6: 0 | AN6: 0 | AO6: 0 | AP6: 0 | AQ6: 0 | AR6: 0 | AS6: 0 | AT6: 0 | AU6: 0 | AV6: 0 | AW6: 0 | AX6: 0 | AY6: 0 | AZ6: 0 | BA6: 0 | BB6: 0 | BC6: 0 | BD6: 0 | BE6: 0 | BF6: 0 | BG6: 0 | BH6: 0 | BI6: 0 | BJ6: 0 | BK6: 0 | BL6: 0 | BM6: 0 | BN6: 0 | BO6: 0 | BP6: 0 | BQ6: 0 | BR6: 0 | BS6: 0 | BT6: 57364.66 | BU6: 230514.72 | BV6: -138.39 | BW6: 21180.058 | BX6: -0.00039 | BY6: -16703.104 | BZ6: 3037066.7 | CA6: -1410633 | CB6: 0 | CC6: 19111.883 | CD6: 0 | CE6: 0 | CF6: 150403.97 | CG6: 2555.72 | CH6: 0 | CI6: 25184.996 | CJ6: -91088.662 | CK6: 0 | CL6: 0 | CM6: 0 | CN6: 0 | CO6: 0 | CP6: 0 | CQ6: 0 | CR6: 0 | CS6: 0 | CT6: 0 | CU6: 0 | CV6: 0
C7: VENTANILLA
C8: SALDO NETO INICIAL PAGADURÍA | D8: =D5+D6+D7 -> 383379.22 | E8: =E5+E6+E7 -> 1.0576937e+08 | F8: =F5+F6+F7 -> 8080834.4 | G8: =G5+G6+G7 -> 0 | H8: =H5+H6+H7 -> 0 | I8: =I5+I6+I7 -> 74955.182 | J8: =J5+J6+J7 -> 0 | K8: =K5+K6+K7 -> 62362.027 | ... BX8: =BX5+BX6+BX7 -> 22663.665 | BY8: =+BY5+BY6+BY7:BZ7 -> 1075595.8 | BZ8: =BZ5+BZ6+BZ7 -> 2929350.5 | CA8: =CA5+CA6+CA7 -> 2639250.6 | CB8: =CB5+CB6+CB7 -> 19818.566 | CC8: =CC5+CC6+CC7 -> 1086997.7 | CD8: =CD5+CD6+CD7 -> 0 | CE8: =CE5+CE6+CE7 -> 23629.153 | CF8: =CF5+CF6+CF7 -> 870371.13 | CG8: =CG5+CG6+CG7 -> 443898.85 | ... CV8: =CV5+CV6+CV7 -> 20149.388 | CW8: =D8+E8+F8+G8+H8+I8+J8+K8+L8+M8+O8+Q8+S8+U8+W8+Y8+AA8+AC8+AE8+AG8+AI8+AK8+AL8+AM8+AQ8+AR8+AS8+AT8+AU8+AV8+AW8+AX8+AY8+AZ8+BA8+BB8+BC8+BD8+BE8+BF8+BG8+BH8+BI8+BJ8+BK8+BS8+BU8+BV8+BW8+BX8+BY8+BZ8+CA8+CB8+CC8+CD8+CE8+CF8+CG8+CH8+CI8+CJ8+BL8+BM8+BN8+BO8+BP8+BQ8+CK8+CL8+CM8+CN8+CO8+CP8+CQ8+AN8+AO8+AP8+CR8+CT8+CV8 -> 4.5625445e+08
A9: RENTA FIJA | B9: I | C9: PAGOS INTERCOMPAÑÍAS | CW9: =D9+E9+F9+G9+H9+I9+J9+K9+L9+M9+O9+Q9+S9+U9+W9+Y9+AA9+AC9+AE9+AG9+AI9+AK9+AL9+AM9+AQ9+AR9+AS9+AT9+AU9+AV9+AW9+AX9+AY9+AZ9+BA9+BB9+BC9+BD9+BE9+BF9+BG9+BH9+BI9+BJ9+BK9+BS9+BU9+BV9+BW9+BX9+BY9+BZ9+CA9+CB9+CC9+CD9+CE9+CF9+CG9+CH9+CI9+CJ9+BL9+BM9+BN9+BO9+BP9+BQ9+CK9+CL9+CM9+CN9+CO9+CP9+CQ9+AN9+AO9+AP9+CR9+CT9+CV9 -> 0
B10: E | C10: PAGOS INTERCOMPAÑÍAS | CW10: =D10+E10+F10+G10+H10+I10+J10+K10+L10+M10+O10+Q10+S10+U10+W10+Y10+AA10+AC10+AE10+AG10+AI10+AK10+AL10+AM10+AQ10+AR10+AS10+AT10+AU10+AV10+AW10+AX10+AY10+AZ10+BA10+BB10+BC10+BD10+BE10+BF10+BG10+BH10+BI10+BJ10+BK10+BS10+BU10+BV10+BW10+BX10+BY10+BZ10+CA10+CB10+CC10+CD10+CE10+CF10+CG10+CH10+CI10+CJ10+BL10+BM10+BN10+BO10+BP10+BQ10+CK10+CL10+CM10+CN10+CO10+CP10+CQ10+AN10+AO10+AP10+CR10+CT10+CV10 -> 0
B11: I | C11: INGRESOS INTERESES | L11: =16059+382605+832068 -> 1230732 | M11: 118465 | CW11: =D11+E11+F11+G11+H11+I11+J11+K11+L11+M11+O11+Q11+S11+U11+W11+Y11+AA11+AC11+AE11+AG11+AI11+AK11+AL11+AM11+AQ11+AR11+AS11+AT11+AU11+AV11+AW11+AX11+AY11+AZ11+BA11+BB11+BC11+BD11+BE11+BF11+BG11+BH11+BI11+BJ11+BK11+BS11+BU11+BV11+BW11+BX11+BY11+BZ11+CA11+CB11+CC11+CD11+CE11+CF11+CG11+CH11+CI11+CJ11+BL11+BM11+BN11+BO11+BP11+BQ11+CK11+CL11+CM11+CN11+CO11+CP11+CQ11+AN11+AO11+AP11+CR11+CT11+CV11 -> 1349197
B12: I | C12: INGRESO REDENCIÓN TÍTULOS | CW12: =D12+E12+F12+G12+H12+I12+J12+K12+L12+M12+O12+Q12+S12+U12+W12+Y12+AA12+AC12+AE12+AG12+AI12+AK12+AL12+AM12+AQ12+AR12+AS12+AT12+AU12+AV12+AW12+AX12+AY12+AZ12+BA12+BB12+BC12+BD12+BE12+BF12+BG12+BH12+BI12+BJ12+BK12+BS12+BU12+BV12+BW12+BX12+BY12+BZ12+CA12+CB12+CC12+CD12+CE12+CF12+CG12+CH12+CI12+CJ12+BL12+BM12+BN12+BO12+BP12+BQ12+CK12+CL12+CM12+CN12+CO12+CP12+CQ12+AN12+AO12+AP12+CR12+CT12+CV12 -> 0
B13: E | C13: APERTURA ACTIVO FINANCIERO | CW13: =D13+E13+F13+G13+H13+I13+J13+K13+L13+M13+O13+Q13+S13+U13+W13+Y13+AA13+AC13+AE13+AG13+AI13+AK13+AL13+AM13+AQ13+AR13+AS13+AT13+AU13+AV13+AW13+AX13+AY13+AZ13+BA13+BB13+BC13+BD13+BE13+BF13+BG13+BH13+BI13+BJ13+BK13+BS13+BU13+BV13+BW13+BX13+BY13+BZ13+CA13+CB13+CC13+CD13+CE13+CF13+CG13+CH13+CI13+CJ13+BL13+BM13+BN13+BO13+BP13+BQ13+CK13+CL13+CM13+CN13+CO13+CP13+CQ13+AN13+AO13+AP13+CR13+CT13+CV13 -> 0
B14: I | C14: CANCELACIÓN ACTIVO FINANCIERO | CW14: =D14+E14+F14+G14+H14+I14+J14+K14+L14+M14+O14+Q14+S14+U14+W14+Y14+AA14+AC14+AE14+AG14+AI14+AK14+AL14+AM14+AQ14+AR14+AS14+AT14+AU14+AV14+AW14+AX14+AY14+AZ14+BA14+BB14+BC14+BD14+BE14+BF14+BG14+BH14+BI14+BJ14+BK14+BS14+BU14+BV14+BW14+BX14+BY14+BZ14+CA14+CB14+CC14+CD14+CE14+CF14+CG14+CH14+CI14+CJ14+BL14+BM14+BN14+BO14+BP14+BQ14+CK14+CL14+CM14+CN14+CO14+CP14+CQ14+AN14+AO14+AP14+CR14+CT14+CV14 -> 0
B15: I | C15: INTERESES ACTIVO FINANCIERO | CW15: =D15+E15+F15+G15+H15+I15+J15+K15+L15+M15+O15+Q15+S15+U15+W15+Y15+AA15+AC15+AE15+AG15+AI15+AK15+AL15+AM15+AQ15+AR15+AS15+AT15+AU15+AV15+AW15+AX15+AY15+AZ15+BA15+BB15+BC15+BD15+BE15+BF15+BG15+BH15+BI15+BJ15+BK15+BS15+BU15+BV15+BW15+BX15+BY15+BZ15+CA15+CB15+CC15+CD15+CE15+CF15+CG15+CH15+CI15+CJ15+BL15+BM15+BN15+BO15+BP15+BQ15+CK15+CL15+CM15+CN15+CO15+CP15+CQ15+AN15+AO15+AP15+CR15+CT15+CV15 -> 0
B16: E | C16: CANCELACIÓN KW | CW16: =D16+E16+F16+G16+H16+I16+J16+K16+L16+M16+O16+Q16+S16+U16+W16+Y16+AA16+AC16+AE16+AG16+AI16+AK16+AL16+AM16+AQ16+AR16+AS16+AT16+AU16+AV16+AW16+AX16+AY16+AZ16+BA16+BB16+BC16+BD16+BE16+BF16+BG16+BH16+BI16+BJ16+BK16+BS16+BU16+BV16+BW16+BX16+BY16+BZ16+CA16+CB16+CC16+CD16+CE16+CF16+CG16+CH16+CI16+CJ16+BL16+BM16+BN16+BO16+BP16+BQ16+CK16+CL16+CM16+CN16+CO16+CP16+CQ16+AN16+AO16+AP16+CR16+CT16+CV16 -> 0
B17: E | C17: PAGO INTERESES KW | CW17: =D17+E17+F17+G17+H17+I17+J17+K17+L17+M17+O17+Q17+S17+U17+W17+Y17+AA17+AC17+AE17+AG17+AI17+AK17+AL17+AM17+AQ17+AR17+AS17+AT17+AU17+AV17+AW17+AX17+AY17+AZ17+BA17+BB17+BC17+BD17+BE17+BF17+BG17+BH17+BI17+BJ17+BK17+BS17+BU17+BV17+BW17+BX17+BY17+BZ17+CA17+CB17+CC17+CD17+CE17+CF17+CG17+CH17+CI17+CJ17+BL17+BM17+BN17+BO17+BP17+BQ17+CK17+CL17+CM17+CN17+CO17+CP17+CQ17+AN17+AO17+AP17+CR17+CT17+CV17 -> 0
B18: I | C18: APERTURA KW | CW18: =D18+E18+F18+G18+H18+I18+J18+K18+L18+M18+O18+Q18+S18+U18+W18+Y18+AA18+AC18+AE18+AG18+AI18+AK18+AL18+AM18+AQ18+AR18+AS18+AT18+AU18+AV18+AW18+AX18+AY18+AZ18+BA18+BB18+BC18+BD18+BE18+BF18+BG18+BH18+BI18+BJ18+BK18+BS18+BU18+BV18+BW18+BX18+BY18+BZ18+CA18+CB18+CC18+CD18+CE18+CF18+CG18+CH18+CI18+CJ18+BL18+BM18+BN18+BO18+BP18+BQ18+CK18+CL18+CM18+CN18+CO18+CP18+CQ18+AN18+AO18+AP18+CR18+CT18+CV18 -> 0
B19: E | C19: COMPRA TÍTULOS | CW19: =D19+E19+F19+G19+H19+I19+J19+K19+L19+M19+O19+Q19+S19+U19+W19+Y19+AA19+AC19+AE19+AG19+AI19+AK19+AL19+AM19+AQ19+AR19+AS19+AT19+AU19+AV19+AW19+AX19+AY19+AZ19+BA19+BB19+BC19+BD19+BE19+BF19+BG19+BH19+BI19+BJ19+BK19+BS19+BU19+BV19+BW19+BX19+BY19+BZ19+CA19+CB19+CC19+CD19+CE19+CF19+CG19+CH19+CI19+CJ19+BL19+BM19+BN19+BO19+BP19+BQ19+CK19+CL19+CM19+CN19+CO19+CP19+CQ19+AN19+AO19+AP19+CR19+CT19+CV19 -> 0
B20: E | C20: COMPRA SIMULTÁNEA ACTIVA | L20: -74030460 | M20: -58332630 | CW20: =D20+E20+F20+G20+H20+I20+J20+K20+L20+M20+O20+Q20+S20+U20+W20+Y20+AA20+AC20+AE20+AG20+AI20+AK20+AL20+AM20+AQ20+AR20+AS20+AT20+AU20+AV20+AW20+AX20+AY20+AZ20+BA20+BB20+BC20+BD20+BE20+BF20+BG20+BH20+BI20+BJ20+BK20+BS20+BU20+BV20+BW20+BX20+BY20+BZ20+CA20+CB20+CC20+CD20+CE20+CF20+CG20+CH20+CI20+CJ20+BL20+BM20+BN20+BO20+BP20+BQ20+CK20+CL20+CM20+CN20+CO20+CP20+CQ20+AN20+AO20+AP20+CR20+CT20+CV20 -> -132363090
B21: E | C21: REDENCIÓN SIMULTÁNEA PASIVA | L21: -58154269 | CW21: =D21+E21+F21+G21+H21+I21+J21+K21+L21+M21+O21+Q21+S21+U21+W21+Y21+AA21+AC21+AE21+AG21+AI21+AK21+AL21+AM21+AQ21+AR21+AS21+AT21+AU21+AV21+AW21+AX21+AY21+AZ21+BA21+BB21+BC21+BD21+BE21+BF21+BG21+BH21+BI21+BJ21+BK21+BS21+BU21+BV21+BW21+BX21+BY21+BZ21+CA21+CB21+CC21+CD21+CE21+CF21+CG21+CH21+CI21+CJ21+BL21+BM21+BN21+BO21+BP21+BQ21+CK21+CL21+CM21+CN21+CO21+CP21+CQ21+AN21+AO21+AP21+CR21+CT21+CV21 -> -58154269
B22: I | C22: VENTA TÍTULOS | P22: =9751472.23+3427302.08 -> 13178774 | Q22: =(P22*4018.41)/1000 -> 52957718 | CW22: =D22+E22+F22+G22+H22+I22+J22+K22+L22+M22+O22+Q22+S22+U22+W22+Y22+AA22+AC22+AE22+AG22+AI22+AK22+AL22+AM22+AQ22+AR22+AS22+AT22+AU22+AV22+AW22+AX22+AY22+AZ22+BA22+BB22+BC22+BD22+BE22+BF22+BG22+BH22+BI22+BJ22+BK22+BS22+BU22+BV22+BW22+BX22+BY22+BZ22+CA22+CB22+CC22+CD22+CE22+CF22+CG22+CH22+CI22+CJ22+BL22+BM22+BN22+BO22+BP22+BQ22+CK22+CL22+CM22+CN22+CO22+CP22+CQ22+AN22+AO22+AP22+CR22+CT22+CV22 -> 52957718
B23: I | C23: COMPRA SIMULTÁNEA PASIVA | L23: 35420605 | CW23: =D23+E23+F23+G23+H23+I23+J23+K23+L23+M23+O23+Q23+S23+U23+W23+Y23+AA23+AC23+AE23+AG23+AI23+AK23+AL23+AM23+AQ23+AR23+AS23+AT23+AU23+AV23+AW23+AX23+AY23+AZ23+BA23+BB23+BC23+BD23+BE23+BF23+BG23+BH23+BI23+BJ23+BK23+BS23+BU23+BV23+BW23+BX23+BY23+BZ23+CA23+CB23+CC23+CD23+CE23+CF23+CG23+CH23+CI23+CJ23+BL23+BM23+BN23+BO23+BP23+BQ23+CK23+CL23+CM23+CN23+CO23+CP23+CQ23+AN23+AO23+AP23+CR23+CT23+CV23 -> 35420605
B24: I | C24: REDENCIÓN SIMULTÁNEA ACTIVA | L24: 8145584.5 | M24: 58695956 | CW24: =D24+E24+F24+G24+H24+I24+J24+K24+L24+M24+O24+Q24+S24+U24+W24+Y24+AA24+AC24+AE24+AG24+AI24+AK24+AL24+AM24+AQ24+AR24+AS24+AT24+AU24+AV24+AW24+AX24+AY24+AZ24+BA24+BB24+BC24+BD24+BE24+BF24+BG24+BH24+BI24+BJ24+BK24+BS24+BU24+BV24+BW24+BX24+BY24+BZ24+CA24+CB24+CC24+CD24+CE24+CF24+CG24+CH24+CI24+CJ24+BL24+BM24+BN24+BO24+BP24+BQ24+CK24+CL24+CM24+CN24+CO24+CP24+CQ24+AN24+AO24+AP24+CR24+CT24+CV24 -> 66841541
B25: I | C25: DISTRIBUCIÓN FCP | CW25: =D25+E25+F25+G25+H25+I25+J25+K25+L25+M25+O25+Q25+S25+U25+W25+Y25+AA25+AC25+AE25+AG25+AI25+AK25+AL25+AM25+AQ25+AR25+AS25+AT25+AU25+AV25+AW25+AX25+AY25+AZ25+BA25+BB25+BC25+BD25+BE25+BF25+BG25+BH25+BI25+BJ25+BK25+BS25+BU25+BV25+BW25+BX25+BY25+BZ25+CA25+CB25+CC25+CD25+CE25+CF25+CG25+CH25+CI25+CJ25+BL25+BM25+BN25+BO25+BP25+BQ25+CK25+CL25+CM25+CN25+CO25+CP25+CQ25+AN25+AO25+AP25+CR25+CT25+CV25 -> 0
B26: E | C26: LLAMADO CAPITAL FCP | CW26: =D26+E26+F26+G26+H26+I26+J26+K26+L26+M26+O26+Q26+S26+U26+W26+Y26+AA26+AC26+AE26+AG26+AI26+AK26+AL26+AM26+AQ26+AR26+AS26+AT26+AU26+AV26+AW26+AX26+AY26+AZ26+BA26+BB26+BC26+BD26+BE26+BF26+BG26+BH26+BI26+BJ26+BK26+BS26+BU26+BV26+BW26+BX26+BY26+BZ26+CA26+CB26+CC26+CD26+CE26+CF26+CG26+CH26+CI26+CJ26+BL26+BM26+BN26+BO26+BP26+BQ26+CK26+CL26+CM26+CN26+CO26+CP26+CQ26+AN26+AO26+AP26+CR26+CT26+CV26 -> 0
B27: I | C27: RETIRO DE CAPITAL ENCARGOS | D27: 53000 | F27: =2875000+20000000 -> 22875000 | CA27: 1000000 | CW27: =D27+E27+F27+G27+H27+I27+J27+K27+L27+M27+O27+Q27+S27+U27+W27+Y27+AA27+AC27+AE27+AG27+AI27+AK27+AL27+AM27+AQ27+AR27+AS27+AT27+AU27+AV27+AW27+AX27+AY27+AZ27+BA27+BB27+BC27+BD27+BE27+BF27+BG27+BH27+BI27+BJ27+BK27+BS27+BU27+BV27+BW27+BX27+BY27+BZ27+CA27+CB27+CC27+CD27+CE27+CF27+CG27+CH27+CI27+CJ27+BL27+BM27+BN27+BO27+BP27+BQ27+CK27+CL27+CM27+CN27+CO27+CP27+CQ27+AN27+AO27+AP27+CR27+CT27+CV27 -> 23928000
B28: E | C28: INCREMENTO DE CAPITAL ENCARGOS | E28: -7531000 | M28: -500000 | CW28: =D28+E28+F28+G28+H28+I28+J28+K28+L28+M28+O28+Q28+S28+U28+W28+Y28+AA28+AC28+AE28+AG28+AI28+AK28+AL28+AM28+AQ28+AR28+AS28+AT28+AU28+AV28+AW28+AX28+AY28+AZ28+BA28+BB28+BC28+BD28+BE28+BF28+BG28+BH28+BI28+BJ28+BK28+BS28+BU28+BV28+BW28+BX28+BY28+BZ28+CA28+CB28+CC28+CD28+CE28+CF28+CG28+CH28+CI28+CJ28+BL28+BM28+BN28+BO28+BP28+BQ28+CK28+CL28+CM28+CN28+CO28+CP28+CQ28+AN28+AO28+AP28+CR28+CT28+CV28 -> -8031000
C29: TRASLADO ARL | E29: =-87000000+87000000-87000000 -> -87000000 | L29: 87000000 | CW29: =D29+E29+F29+G29+H29+I29+J29+K29+L29+M29+O29+Q29+S29+U29+W29+Y29+AA29+AC29+AE29+AG29+AI29+AK29+AL29+AM29+AQ29+AR29+AS29+AT29+AU29+AV29+AW29+AX29+AY29+AZ29+BA29+BB29+BC29+BD29+BE29+BF29+BG29+BH29+BI29+BJ29+BK29+BS29+BU29+BV29+BW29+BX29+BY29+BZ29+CA29+CB29+CC29+CD29+CE29+CF29+CG29+CH29+CI29+CJ29+BL29+BM29+BN29+BO29+BP29+BQ29+CK29+CL29+CM29+CN29+CO29+CP29+CQ29+AN29+AO29+AP29+CR29+CT29+CV29 -> 0
A30: RENTA VARIABLE | B30: E | C30: COMPRA ACCIONES | CW30: =D30+E30+F30+G30+H30+I30+J30+K30+L30+M30+O30+Q30+S30+U30+W30+Y30+AA30+AC30+AE30+AG30+AI30+AK30+AL30+AM30+AQ30+AR30+AS30+AT30+AU30+AV30+AW30+AX30+AY30+AZ30+BA30+BB30+BC30+BD30+BE30+BF30+BG30+BH30+BI30+BJ30+BK30+BS30+BU30+BV30+BW30+BX30+BY30+BZ30+CA30+CB30+CC30+CD30+CE30+CF30+CG30+CH30+CI30+CJ30+BL30+BM30+BN30+BO30+BP30+BQ30+CK30+CL30+CM30+CN30+CO30+CP30+CQ30+AN30+AO30+AP30+CR30+CT30+CV30 -> 0
B31: I | C31: VENTA ACCIONES | L31: 564529.35 | CW31: =D31+E31+F31+G31+H31+I31+J31+K31+L31+M31+O31+Q31+S31+U31+W31+Y31+AA31+AC31+AE31+AG31+AI31+AK31+AL31+AM31+AQ31+AR31+AS31+AT31+AU31+AV31+AW31+AX31+AY31+AZ31+BA31+BB31+BC31+BD31+BE31+BF31+BG31+BH31+BI31+BJ31+BK31+BS31+BU31+BV31+BW31+BX31+BY31+BZ31+CA31+CB31+CC31+CD31+CE31+CF31+CG31+CH31+CI31+CJ31+BL31+BM31+BN31+BO31+BP31+BQ31+CK31+CL31+CM31+CN31+CO31+CP31+CQ31+AN31+AO31+AP31+CR31+CT31+CV31 -> 564529.35
B32: I | C32: INGRESO DIVIDENDOS | CW32: =D32+E32+F32+G32+H32+I32+J32+K32+L32+M32+O32+Q32+S32+U32+W32+Y32+AA32+AC32+AE32+AG32+AI32+AK32+AL32+AM32+AQ32+AR32+AS32+AT32+AU32+AV32+AW32+AX32+AY32+AZ32+BA32+BB32+BC32+BD32+BE32+BF32+BG32+BH32+BI32+BJ32+BK32+BS32+BU32+BV32+BW32+BX32+BY32+BZ32+CA32+CB32+CC32+CD32+CE32+CF32+CG32+CH32+CI32+CJ32+BL32+BM32+BN32+BO32+BP32+BQ32+CK32+CL32+CM32+CN32+CO32+CP32+CQ32+AN32+AO32+AP32+CR32+CT32+CV32 -> 0
B33: E | C33: EGRESO DIVIDENDOS | CW33: =D33+E33+F33+G33+H33+I33+J33+K33+L33+M33+O33+Q33+S33+U33+W33+Y33+AA33+AC33+AE33+AG33+AI33+AK33+AL33+AM33+AQ33+AR33+AS33+AT33+AU33+AV33+AW33+AX33+AY33+AZ33+BA33+BB33+BC33+BD33+BE33+BF33+BG33+BH33+BI33+BJ33+BK33+BS33+BU33+BV33+BW33+BX33+BY33+BZ33+CA33+CB33+CC33+CD33+CE33+CF33+CG33+CH33+CI33+CJ33+BL33+BM33+BN33+BO33+BP33+BQ33+CK33+CL33+CM33+CN33+CO33+CP33+CQ33+AN33+AO33+AP33+CR33+CT33+CV33 -> 0
B34: I | C34: INGRESO DIVIDENDOS ETF | CW34: =D34+E34+F34+G34+H34+I34+J34+K34+L34+M34+O34+Q34+S34+U34+W34+Y34+AA34+AC34+AE34+AG34+AI34+AK34+AL34+AM34+AQ34+AR34+AS34+AT34+AU34+AV34+AW34+AX34+AY34+AZ34+BA34+BB34+BC34+BD34+BE34+BF34+BG34+BH34+BI34+BJ34+BK34+BS34+BU34+BV34+BW34+BX34+BY34+BZ34+CA34+CB34+CC34+CD34+CE34+CF34+CG34+CH34+CI34+CJ34+BL34+BM34+BN34+BO34+BP34+BQ34+CK34+CL34+CM34+CN34+CO34+CP34+CQ34+AN34+AO34+AP34+CR34+CT34+CV34 -> 0
A35: DERIVADOS | C35: SWAP | P35: 2125024 | Q35: =(P35*4018.41)/1000 -> 8539217.7 | V35: 990000 | W35: =(V35*4018.41)/1000 -> 3978225.9 | CW35: =D35+E35+F35+G35+H35+I35+J35+K35+L35+M35+O35+Q35+S35+U35+W35+Y35+AA35+AC35+AE35+AG35+AI35+AK35+AL35+AM35+AQ35+AR35+AS35+AT35+AU35+AV35+AW35+AX35+AY35+AZ35+BA35+BB35+BC35+BD35+BE35+BF35+BG35+BH35+BI35+BJ35+BK35+BS35+BU35+BV35+BW35+BX35+BY35+BZ35+CA35+CB35+CC35+CD35+CE35+CF35+CG35+CH35+CI35+CJ35+BL35+BM35+BN35+BO35+BP35+BQ35+CK35+CL35+CM35+CN35+CO35+CP35+CQ35+AN35+AO35+AP35+CR35+CT35+CV35 -> 12517444
B36: E | C36: OPCIONES | CW36: =D36+E36+F36+G36+H36+I36+J36+K36+L36+M36+O36+Q36+S36+U36+W36+Y36+AA36+AC36+AE36+AG36+AI36+AK36+AL36+AM36+AQ36+AR36+AS36+AT36+AU36+AV36+AW36+AX36+AY36+AZ36+BA36+BB36+BC36+BD36+BE36+BF36+BG36+BH36+BI36+BJ36+BK36+BS36+BU36+BV36+BW36+BX36+BY36+BZ36+CA36+CB36+CC36+CD36+CE36+CF36+CG36+CH36+CI36+CJ36+BL36+BM36+BN36+BO36+BP36+BQ36+CK36+CL36+CM36+CN36+CO36+CP36+CQ36+AN36+AO36+AP36+CR36+CT36+CV36 -> 0
B37: I | C37: OPCIONES | CW37: =D37+E37+F37+G37+H37+I37+J37+K37+L37+M37+O37+Q37+S37+U37+W37+Y37+AA37+AC37+AE37+AG37+AI37+AK37+AL37+AM37+AQ37+AR37+AS37+AT37+AU37+AV37+AW37+AX37+AY37+AZ37+BA37+BB37+BC37+BD37+BE37+BF37+BG37+BH37+BI37+BJ37+BK37+BS37+BU37+BV37+BW37+BX37+BY37+BZ37+CA37+CB37+CC37+CD37+CE37+CF37+CG37+CH37+CI37+CJ37+BL37+BM37+BN37+BO37+BP37+BQ37+CK37+CL37+CM37+CN37+CO37+CP37+CQ37+AN37+AO37+AP37+CR37+CT37+CV37 -> 0
B38: E | C38: FORWARD | CW38: =D38+E38+F38+G38+H38+I38+J38+K38+L38+M38+O38+Q38+S38+U38+W38+Y38+AA38+AC38+AE38+AG38+AI38+AK38+AL38+AM38+AQ38+AR38+AS38+AT38+AU38+AV38+AW38+AX38+AY38+AZ38+BA38+BB38+BC38+BD38+BE38+BF38+BG38+BH38+BI38+BJ38+BK38+BS38+BU38+BV38+BW38+BX38+BY38+BZ38+CA38+CB38+CC38+CD38+CE38+CF38+CG38+CH38+CI38+CJ38+BL38+BM38+BN38+BO38+BP38+BQ38+CK38+CL38+CM38+CN38+CO38+CP38+CQ38+AN38+AO38+AP38+CR38+CT38+CV38 -> 0
B39: I | C39: FORWARD | CW39: =D39+E39+F39+G39+H39+I39+J39+K39+L39+M39+O39+Q39+S39+U39+W39+Y39+AA39+AC39+AE39+AG39+AI39+AK39+AL39+AM39+AQ39+AR39+AS39+AT39+AU39+AV39+AW39+AX39+AY39+AZ39+BA39+BB39+BC39+BD39+BE39+BF39+BG39+BH39+BI39+BJ39+BK39+BS39+BU39+BV39+BW39+BX39+BY39+BZ39+CA39+CB39+CC39+CD39+CE39+CF39+CG39+CH39+CI39+CJ39+BL39+BM39+BN39+BO39+BP39+BQ39+CK39+CL39+CM39+CN39+CO39+CP39+CQ39+AN39+AO39+AP39+CR39+CT39+CV39 -> 0
A40: DIVISAS | B40: E | C40: COMPRA DIVISAS OTRAS ÁREAS | CW40: =D40+E40+F40+G40+H40+I40+J40+K40+L40+M40+O40+Q40+S40+U40+W40+Y40+AA40+AC40+AE40+AG40+AI40+AK40+AL40+AM40+AQ40+AR40+AS40+AT40+AU40+AV40+AW40+AX40+AY40+AZ40+BA40+BB40+BC40+BD40+BE40+BF40+BG40+BH40+BI40+BJ40+BK40+BS40+BU40+BV40+BW40+BX40+BY40+BZ40+CA40+CB40+CC40+CD40+CE40+CF40+CG40+CH40+CI40+CJ40+BL40+BM40+BN40+BO40+BP40+BQ40+CK40+CL40+CM40+CN40+CO40+CP40+CQ40+AN40+AO40+AP40+CR40+CT40+CV40 -> 0
...

Sheet SEP 03
D1: OPERACIONES DE TESORERÍA | BL1: LIBRE INVERSION | BO1: FIC LIFE USD | BP1: FIC VIDA PESOS | BQ1: FIC LATIN VIDA PESOS | BR1: PAGADURÍA
D2: CAPITALIZADORA | E2: SEGUROS BOLÍVAR | F2: COMERCIALES | G2: CAPITALIZADORA AHO | H2: SEGUROS BOLÍVAR AHO | I2: SEGUROS BOLÍVAR ARL | J2: COMERCIALES AHO | K2: CAPITALIZADORA | L2: SEGUROS BOLÍVAR | M2: COMERCIALES | N2: CAPITALIZADORA US$ | O2: CAPITALIZADORA PESOS | P2: SEGUROS BOLÍVAR US$ | Q2: SEGUROS BOLÍVAR PESOS | R2: COMERCIALES US$ | S2: COMERCIALES PESOS | T2: CAPITALIZADORA US$ | U2: CAPITALIZADORA PESOS | V2: SEGUROS BOLÍVAR US$ | W2: SEGUROS BOLÍVAR PESOS | X2: COMERCIALES US$ | Y2: COMERCIALES PESOS | Z2: CAPITALIZADORA US$ | AA2: CAPITALIZADORA PESOS | AB2: SEGUROS BOLÍVAR US$ | AC2: SEGUROS BOLÍVAR PESOS | AD2: COMERCIALES US$ | AE2: COMERCIALES PESOS | AF2: GRUPO BOLIVAR US$ | AG2: GRUPO BOLIVAR PESOS | AH2: SEISA US$ | AI2: SEISA PESOS | AJ2: RIBI US$ | AK2: RIBI PESOS | AL2: GRUPO BOLIVAR | AM2: INVERSORAS | AN2: SALUD EPS BOLIVAR | AO2: SALUD IPS BOLIVAR | AP2: SERVICIOS BOLIVAR | AQ2: SERVICIOS BOLIVAR | AR2: CAPITALIZADORA | AS2: SEGUROS BOLÍVAR | AT2: SEGUROS BOLÍVAR ARL | AU2: COMERCIALES | AV2: GRUPO BOLIVAR | AW2: CAPITALIZADORA | AX2: SEGUROS BOLÍVAR | AY2: COMERCIALES | AZ2: GRUPO BOLIVAR | BA2: CAPITALIZADORA | BB2: SEGUROS BOLÍVAR | BC2: SEGUROS BOLÍVAR ARL | BD2: COMERCIALES | BE2: CAPITALIZADORA | BF2: SEGUROS BOLÍVAR | BG2: COMERCIALES | BH2: CAPITALIZADORA | BI2: SEGUROS BOLÍVAR | BJ2: COMERCIALES | BK2: GRUPO BOLIVAR | BL2: CAPITALIZADORA AHO | BM2: SEGUROS BOLÍVAR AHO | BN2: COMERCIALES AHO | BO2: SEGUROS BOLÍVAR AHO | BP2: SEGUROS BOLÍVAR AHO | BQ2: SEGUROS BOLÍVAR AHO | BR2: SEGUROS BOLÍVAR USD | BS2: SEGUROS BOLÍVAR PESOS | BT2: COMERCIALES USD | BU2: COMERCIALES PESOS | BV2: CAPITALIZADORA | BW2: SEGUROS BOLÍVAR | BX2: COMERCIALES | BY2: CAPITALIZADORA | BZ2: SEGUROS BOLÍVAR | CA2: COMERCIALES | CB2: CAPITALIZADORA | CC2: SEGUROS BOLÍVAR | CD2: COMERCIALES | CE2: CAPITALIZADORA | CF2: SEGUROS BOLÍVAR | CG2: COMERCIALES | CH2: COMERCIALES | CI2: SEGUROS BOLÍVAR | CJ2: COMERCIALES | CK2: SEGUROS BOLÍVAR | CL2: SEGUROS BOLÍVAR | CM2: SEGUROS BOLÍVAR | CN2: SEGUROS BOLÍVAR | CO2: SEGUROS BOLÍVAR | CP2: SEGUROS BOLÍVAR | CQ2: SEGUROS BOLÍVAR | CR2: SEGUROS BOLÍVAR | CS2: SEGUROS BOLÍVAR USD | CT2: SEGUROS BOLÍVAR PESOS | CU2: COMERCIALES USD | CV2: COMERCIALES PESOS | CW2: TOTALES
D3: BANCO DAVIVIENDA | E3: BANCO DAVIVIENDA | F3: BANCO DAVIVIENDA | G3: BANCO DAVIVIENDA | H3: BANCO DAVIVIENDA | I3: BANCO DAVIVIENDA | J3: BANCO DAVIVIENDA | K3: BANCO REPUBLICA | L3: BANCO REPUBLICA | M3: BANCO REPUBLICA | N3: CITIBANK COMP | O3: CITIBANK COMP | P3: CITIBANK COMP | Q3: CITIBANK COMP | R3: CITIBANK COMP | S3: CITIBANK COMP | T3: JP MORGAN | U3: JP MORGAN | V3: JP MORGAN | W3: JP MORGAN | X3: JP MORGAN | Y3: JP MORGAN | Z3: DAVIVIENDA INT | AA3: DAVIVIENDA INT | AB3: DAVIVIENDA INT | AC3: DAVIVIENDA INT | AD3: DAVIVIENDA INT | AE3: DAVIVIENDA INT | AF3: DAVIVIENDA INT | AG3: DAVIVIENDA INT | AH3: DAVIVIENDA INT | AI3: DAVIVIENDA INT | AJ3: DAVIVIENDA INT | AK3: DAVIVIENDA INT | AL3: DAVIVIENDA | AM3: DAVIVIENDA | AQ3: FACILITIES | AR3: BANCO DE BOGOTA | AS3: BANCO DE BOGOTA | AT3: BANCO DE BOGOTA | AU3: BANCO DE BOGOTA | AV3: BANCO DE BOGOTA | AW3: ITAÚ | AX3: ITAÚ | AY3: ITAÚ | AZ3: ITAÚ | BA3: CORFIDIARIO | BB3: CORFIDIARIO | BC3: CORFIDIARIO | BD3: CORFIDIARIO | BE3: BANCO COLPATRIA | BF3: BANCO COLPATRIA | BG3: BANCO COLPATRIA | BH3: BANCOLOMBIA | BI3: BANCOLOMBIA | BJ3: BANCOLOMBIA | BK3: BANCOLOMBIA | BL3: BANCO DAVIVIENDA | BM3: BANCO DAVIVIENDA | BN3: BANCO DAVIVIENDA | BO3: BANCO DAVIVIENDA | BP3: BANCO DAVIVIENDA | BQ3: BANCO DAVIVIENDA | BR3: CITIBANK REASEGUROS | BS3: CITIBANK REASEGUROS | BT3: CITIBANK REASEGUROS | BU3: CITIBANK REASEGUROS | BV3: BANCO DE BOGOTA | BW3: BANCO DE BOGOTA | BX3: BANCO DE BOGOTA | BY3: BANCOLOMBIA | BZ3: BANCOLOMBIA | CA3: BANCOLOMBIA | CB3: BANCO POPULAR | CC3: BANCO POPULAR | CD3: BANCO POPULAR | CE3: BBVA | CF3: BBVA | CG3: BBVA | CH3: BANCO COLPATRIA | CI3: BANCO DE OCCIDENTE | CJ3: BANCO DE OCCIDENTE | CK3: CITIBANK | CL3: CITIBANK | CM3: BANCO DAVIVIENDA | CN3: BANCOLOMBIA | CO3: AV VILLAS - AHO | CP3: BANCO DE OCCIDENTE | CQ3: BANCO DE OCCIDENTE | CR3: BANCO PICHINCHA | CS3: DAVIVIENDA INT REASEGUROS | CT3: DAVIVIENDA INT REASEGUROS | CU3: DAVIVIENDA INT REASEGUROS | CV3: DAVIVIENDA INT REASEGUROS
A4: TIPO OP | B4: OP | C4: CONCEPTO | G4: 482800001265 | H4: 482800001273 | I4: 482800002024 | J4: 482800001257 | K4: 62250766-0 | L4: 62250774-0 | M4: 62250782-0 | N4: 36203301 | O4: 36203301 | P4: 36203328 | Q4: 36203328 | R4: 36025015 | S4: 36025015 | T4: 705329517 | U4: 705329517 | V4: 705300062 | W4: 705300062 | X4: 705300070 | Y4: 705300070 | Z4: 865784010 | AA4: 865784010 | AB4: 865804010 | AC4: 865804010 | AD4: 865794010 | AE4: 865794010 | AF4: 867614010 | AG4: 867614010 | AH4: 010002000127 | AI4: 010002000127 | AJ4: 010003000003 | AK4: 010003000003 | AR4: 000977298 | AS4: 000268649 | AT4: 000977280 | AU4: 000977272 | AV4: 000826701 | AW4: 005597176 | AX4: 005595639 | AY4: 005597183 | AZ4: 005595646 | BA4: 2113700 | BB4: 2114920 | BC4: 2113692 | BD4: 2113718 | BE4: 0172120172 | BF4: 0172120180 | BG4: 0172120199 | BH4: 17171123071 | BI4: 17171122902 | BJ4: 17171123003 | BK4: ´03199361537 | BL4: 482800007882 | BM4: 482800007908 | BN4: 482800007890 | BO4: 482800010001 | BP4: 482800010019 | BQ4: 482800010027 | BR4: 36024995 | BS4: 36024995 | BT4: 36903922 | BU4: 36903922 | BV4: 036273662 | BW4: 036297810 | BX4: 036273688 | BY4: 5300635932 | BZ4: 5300250331 | CA4: 5300218006 | CB4: 40195224 | CC4: 40298119 | CD4: 40299661 | CE4: 137017554 | CF4: 137008629 | CG4: 137017562 | CH4: 121010607 | CI4: 221816614 | CJ4: 221816598 | CK4: 60193029 | CL4: 60193401 | CM4: 1011143807 | CN4: 4801736642 | CO4: 65005340 | CP4: 288086051 | CQ4: 288049109 | CR4: 411166042 | CS4: 865804015 | CT4: 865804015 | CU4: 865794015 | CV4: 865794015
A5: PAGADURÍA | C5: SALDO INICIAL | D5: ='SEP 02'!D55 -> 436379.22 | E5: ='SEP 02'!E55 -> 11237634 | F5: ='SEP 02'!F55 -> 4871281.3 | G5: ='SEP 02'!G55 -> 0 | H5: ='SEP 02'!H55 -> 0 | I5: ='SEP 02'!I55 -> 74968.065 | J5: ='SEP 02'!J55 -> 0 | K5: ='SEP 02'!K55 -> 61430.363 | ... CV5: ='SEP 02'!CV55 -> 20149.388 | CW5: =D5+E5+F5+G5+H5+I5+J5+K5+L5+M5+O5+Q5+S5+U5+W5+Y5+AA5+AC5+AE5+AG5+AI5+AK5+AL5+AM5+AQ5+AR5+AS5+AT5+AU5+AV5+AW5+AX5+AY5+AZ5+BA5+BB5+BC5+BD5+BE5+BF5+BG5+BH5+BI5+BJ5+BK5+BS5+BU5+BV5+BW5+BX5+BY5+BZ5+CA5+CB5+CC5+CD5+CE5+CF5+CG5+CH5+CI5+CJ5+BL5+BM5+BN5+BO5+BP5+BQ5+CK5+CL5+CM5+CN5+CO5+CP5+CQ5+AN5+AO5+AP5+CR5+CT5+CV5 -> 4.5176404e+08
C6: CONSUMO | D6: -53013.077 | E6: 22431227 | F6: 8873792.7 | G6: 0 | H6: 0 | I6: 0 | J6: 0 | K6: 0 | L6: 0 | M6: 0 | N6: 0 | O6: 0 | P6: 0 | Q6: 0 | R6: 0 | S6: 0 | T6: 0 | U6: 0 | V6: 0 | W6: 0 | X6: 0 | Y6: 0 | Z6: 0 | AA6: 0 | AB6: 0 | AC6: 0 | AD6: 0 | AE6: 0 | AF6: 0 | AG6: 0 | AH6: 0 | AI6: 0 | AJ6: 0 | AK6: 0 | AL6: 0 | AM6: 0 | AN6: 0 | AO6: 0 | AP6: 0 | AQ6: 0 | AR6: 0 | AS6: 0 | AT6: 0 | AU6: 0 | AV6: 0 | AW6: 0 | AX6: 0 | AY6: 0 | AZ6: 0 | BA6: 0 | BB6: 0 | BC6: 0 | BD6: 0 | BE6: 0 | BF6: 0 | BG6: 0 | BH6: 0 | BI6: 0 | BJ6: 0 | BK6: 0 | BL6: 0 | BM6: 0 | BN6: 0 | BO6: 0 | BP6: 0 | BQ6: 0 | BR6: 0 | BS6: 0 | BT6: 1920.8 | BU6: 7715.7384 | BV6: -10.736 | BW6: 1255.027 | BX6: 0 | BY6: -11289.609 | BZ6: -3002020.7 | CA6: -3080061.6 | CB6: 0 | CC6: 0 | CD6: 0 | CE6: 3770.489 | CF6: 94761.738 | CG6: 385.686 | CH6: 0 | CI6: 1139.23 | CJ6: 14738.338 | CK6: 0 | CL6: 0 | CM6: 0 | CN6: 0 | CO6: 0 | CP6: 0 | CQ6: 0 | CR6: 0 | CS6: 0 | CT6: 0 | CU6: 0 | CV6: 0
C7: VENTANILLA
C8: SALDO NETO INICIAL PAGADURÍA | D8: =D5+D6+D7 -> 383366.14 | E8: =E5+E6+E7 -> 33668862 | F8: =F5+F6+F7 -> 13745074 | G8: =G5+G6+G7 -> 0 | H8: =H5+H6+H7 -> 0 | I8: =I5+I6+I7 -> 74968.065 | J8: =J5+J6+J7 -> 0 | K8: =K5+K6+K7 -> 61430.363 | ... BX8: =BX5+BX6+BX7 -> 22663.665 | BY8: =+BY5+BY6+BY7:BZ7 -> 1064306.2 | BZ8: =BZ5+BZ6+BZ7 -> -72670.128 | CA8: =CA5+CA6+CA7 -> 559189.01 | CB8: =CB5+CB6+CB7 -> 19818.566 | CC8: =CC5+CC6+CC7 -> 1086997.7 | CD8: =CD5+CD6+CD7 -> 0 | CE8: =CE5+CE6+CE7 -> 27399.642 | CF8: =CF5+CF6+CF7 -> 965132.86 | CG8: =CG5+CG6+CG7 -> 444284.54 | ... CV8: =CV5+CV6+CV7 -> 20149.388 | CW8: =D8+E8+F8+G8+H8+I8+J8+K8+L8+M8+O8+Q8+S8+U8+W8+Y8+AA8+AC8+AE8+AG8+AI8+AK8+AL8+AM8+AQ8+AR8+AS8+AT8+AU8+AV8+AW8+AX8+AY8+AZ8+BA8+BB8+BC8+BD8+BE8+BF8+BG8+BH8+BI8+BJ8+BK8+BS8+BU8+BV8+BW8+BX8+BY8+BZ8+CA8+CB8+CC8+CD8+CE8+CF8+CG8+CH8+CI8+CJ8+BL8+BM8+BN8+BO8+BP8+BQ8+CK8+CL8+CM8+CN8+CO8+CP8+CQ8+AN8+AO8+AP8+CR8+CT8+CV8 -> 4.7704643e+08
A9: RENTA FIJA | B9: I | C9: PAGOS INTERCOMPAÑÍAS | CW9: =D9+E9+F9+G9+H9+I9+J9+K9+L9+M9+O9+Q9+S9+U9+W9+Y9+AA9+AC9+AE9+AG9+AI9+AK9+AL9+AM9+AQ9+AR9+AS9+AT9+AU9+AV9+AW9+AX9+AY9+AZ9+BA9+BB9+BC9+BD9+BE9+BF9+BG9+BH9+BI9+BJ9+BK9+BS9+BU9+BV9+BW9+BX9+BY9+BZ9+CA9+CB9+CC9+CD9+CE9+CF9+CG9+CH9+CI9+CJ9+BL9+BM9+BN9+BO9+BP9+BQ9+CK9+CL9+CM9+CN9+CO9+CP9+CQ9+AN9+AO9+AP9+CR9+CT9+CV9 -> 0
B10: E | C10: PAGOS INTERCOMPAÑÍAS | CW10: =D10+E10+F10+G10+H10+I10+J10+K10+L10+M10+O10+Q10+S10+U10+W10+Y10+AA10+AC10+AE10+AG10+AI10+AK10+AL10+AM10+AQ10+AR10+AS10+AT10+AU10+AV10+AW10+AX10+AY10+AZ10+BA10+BB10+BC10+BD10+BE10+BF10+BG10+BH10+BI10+BJ10+BK10+BS10+BU10+BV10+BW10+BX10+BY10+BZ10+CA10+CB10+CC10+CD10+CE10+CF10+CG10+CH10+CI10+CJ10+BL10+BM10+BN10+BO10+BP10+BQ10+CK10+CL10+CM10+CN10+CO10+CP10+CQ10+AN10+AO10+AP10+CR10+CT10+CV10 -> 0
B11: I | C11: INGRESOS INTERESES | L11: 241720 | M11: =382605+57342.5 -> 439947.5 | P11: 16800 | Q11: =(P11*4016.94)/1000 -> 67484.592 | CW11: =D11+E11+F11+G11+H11+I11+J11+K11+L11+M11+O11+Q11+S11+U11+W11+Y11+AA11+AC11+AE11+AG11+AI11+AK11+AL11+AM11+AQ11+AR11+AS11+AT11+AU11+AV11+AW11+AX11+AY11+AZ11+BA11+BB11+BC11+BD11+BE11+BF11+BG11+BH11+BI11+BJ11+BK11+BS11+BU11+BV11+BW11+BX11+BY11+BZ11+CA11+CB11+CC11+CD11+CE11+CF11+CG11+CH11+CI11+CJ11+BL11+BM11+BN11+BO11+BP11+BQ11+CK11+CL11+CM11+CN11+CO11+CP11+CQ11+AN11+AO11+AP11+CR11+CT11+CV11 -> 749152.09
B12: I | C12: INGRESO REDENCIÓN TÍTULOS | P12: 10000000 | Q12: =(P12*4016.94)/1000 -> 40169400 | CW12: =D12+E12+F12+G12+H12+I12+J12+K12+L12+M12+O12+Q12+S12+U12+W12+Y12+AA12+AC12+AE12+AG12+AI12+AK12+AL12+AM12+AQ12+AR12+AS12+AT12+AU12+AV12+AW12+AX12+AY12+AZ12+BA12+BB12+BC12+BD12+BE12+BF12+BG12+BH12+BI12+BJ12+BK12+BS12+BU12+BV12+BW12+BX12+BY12+BZ12+CA12+CB12+CC12+CD12+CE12+CF12+CG12+CH12+CI12+CJ12+BL12+BM12+BN12+BO12+BP12+BQ12+CK12+CL12+CM12+CN12+CO12+CP12+CQ12+AN12+AO12+AP12+CR12+CT12+CV12 -> 40169400
